 * Debug mode: on
WARNING: This is a development server. Do not use it in a production deployment. Use a production WSGI server instead.
 * Running on all addresses (0.0.0.0)
 * Running on http://127.0.0.1:42598
 * Running on http://167.99.106.139:42598
Press CTRL+C to quit
 * Restarting with stat
 * Debugger is active!
 * Debugger PIN: 895-987-604
61.72.167.71 - - [13/Jun/2023 09:57:40] "POST /SearchVuln/ HTTP/1.1" 200 -
61.72.167.71 - - [13/Jun/2023 09:57:49] "POST /SearchDep/ HTTP/1.1" 200 -
Collecting brotlipy==0.7.0
  Using cached brotlipy-0.7.0-cp38-cp38-manylinux1_x86_64.whl (1.1 MB)
Collecting certifi==2022.12.7
  Using cached certifi-2022.12.7-py3-none-any.whl (155 kB)
Collecting cffi==1.15.1
  Using cached cffi-1.15.1-cp38-cp38-manylinux_2_17_x86_64.manylinux2014_x86_64.whl (442 kB)
Collecting pycparser
  Using cached pycparser-2.21-py2.py3-none-any.whl (118 kB)
Installing collected packages: pycparser, cffi, brotlipy, certifi
Successfully installed brotlipy-0.7.0 certifi-2022.12.7 cffi-1.15.1 pycparser-2.21
Collecting pipdeptree
  Using cached pipdeptree-2.9.0-py3-none-any.whl (18 kB)
Installing collected packages: pipdeptree
Successfully installed pipdeptree-2.9.0
Collecting graphviz
  Using cached graphviz-0.20.1-py3-none-any.whl (47 kB)
Installing collected packages: graphviz
Successfully installed graphviz-0.20.1
Requirement already satisfied: brotlipy==0.7.0 in ./tmp/lib/python3.8/site-packages (from -r requirments.txt (line 1)) (0.7.0)
Requirement already satisfied: certifi==2022.12.7 in ./tmp/lib/python3.8/site-packages (from -r requirments.txt (line 2)) (2022.12.7)
Requirement already satisfied: cffi==1.15.1 in ./tmp/lib/python3.8/site-packages (from -r requirments.txt (line 3)) (1.15.1)
Requirement already satisfied: pycparser in ./tmp/lib/python3.8/site-packages (from cffi==1.15.1->-r requirments.txt (line 3)) (2.21)
Requirement already satisfied: pipdeptree in ./tmp/lib/python3.8/site-packages (2.9.0)
Traceback (most recent call last):
  File "./tmp/bin/pip", line 5, in <module>
  File "/home/m0nd2y/SearchVuln/tmp/lib/python3.8/site-packages/pip/_internal/cli/main.py", line 10, in <module>
  File "/home/m0nd2y/SearchVuln/tmp/lib/python3.8/site-packages/pip/_internal/cli/autocompletion.py", line 9, in <module>
  File "/home/m0nd2y/SearchVuln/tmp/lib/python3.8/site-packages/pip/_internal/cli/main_parser.py", line 7, in <module>
  File "/home/m0nd2y/SearchVuln/tmp/lib/python3.8/site-packages/pip/_internal/cli/cmdoptions.py", line 25, in <module>
ModuleNotFoundError: No module named 'pip._internal.locations'
./make_env.sh: 8: ./tmp/bin/python: not found
61.72.167.71 - - [13/Jun/2023 09:58:03] "POST /SearchDep/ HTTP/1.1" 200 -
127.0.0.1 - - [13/Jun/2023 09:58:27] "POST /SearchDep/ HTTP/1.1" 200 -
ERROR: Invalid requirement: '"' (from line 1 of requirments.txt)
Collecting pipdeptree
  Using cached pipdeptree-2.9.0-py3-none-any.whl (18 kB)
Installing collected packages: pipdeptree
Successfully installed pipdeptree-2.9.0
Collecting graphviz
  Using cached graphviz-0.20.1-py3-none-any.whl (47 kB)
Installing collected packages: graphviz
Successfully installed graphviz-0.20.1
 * Detected change in '/home/m0nd2y/SearchVuln/app.py', reloading
 * Restarting with stat
 * Debugger is active!
 * Debugger PIN: 895-987-604
127.0.0.1 - - [13/Jun/2023 10:02:05] "POST /SearchDep/ HTTP/1.1" 500 -
Traceback (most recent call last):
  File "/home/m0nd2y/.local/lib/python3.8/site-packages/flask_restx/api.py", line 283, in __getattr__
    return getattr(self.default_namespace, name)
AttributeError: 'Namespace' object has no attribute 'paylode'

During handling of the above exception, another exception occurred:

Traceback (most recent call last):
  File "/home/m0nd2y/.local/lib/python3.8/site-packages/flask/app.py", line 2213, in __call__
    return self.wsgi_app(environ, start_response)
  File "/home/m0nd2y/.local/lib/python3.8/site-packages/flask/app.py", line 2193, in wsgi_app
    response = self.handle_exception(e)
  File "/home/m0nd2y/.local/lib/python3.8/site-packages/flask_restx/api.py", line 673, in error_router
    return original_handler(f)
  File "/home/m0nd2y/.local/lib/python3.8/site-packages/flask_restx/api.py", line 671, in error_router
    return self.handle_error(e)
  File "/home/m0nd2y/.local/lib/python3.8/site-packages/flask/app.py", line 2190, in wsgi_app
    response = self.full_dispatch_request()
  File "/home/m0nd2y/.local/lib/python3.8/site-packages/flask/app.py", line 1486, in full_dispatch_request
    rv = self.handle_user_exception(e)
  File "/home/m0nd2y/.local/lib/python3.8/site-packages/flask_restx/api.py", line 673, in error_router
    return original_handler(f)
  File "/home/m0nd2y/.local/lib/python3.8/site-packages/flask_restx/api.py", line 671, in error_router
    return self.handle_error(e)
  File "/home/m0nd2y/.local/lib/python3.8/site-packages/flask/app.py", line 1484, in full_dispatch_request
    rv = self.dispatch_request()
  File "/home/m0nd2y/.local/lib/python3.8/site-packages/flask/app.py", line 1469, in dispatch_request
    return self.ensure_sync(self.view_functions[rule.endpoint])(**view_args)
  File "/home/m0nd2y/.local/lib/python3.8/site-packages/flask_restx/api.py", line 404, in wrapper
    resp = resource(*args, **kwargs)
  File "/home/m0nd2y/.local/lib/python3.8/site-packages/flask/views.py", line 109, in view
    return current_app.ensure_sync(self.dispatch_request)(**kwargs)
  File "/home/m0nd2y/.local/lib/python3.8/site-packages/flask_restx/resource.py", line 46, in dispatch_request
    resp = meth(*args, **kwargs)
  File "/home/m0nd2y/SearchVuln/app.py", line 56, in post
    print(api.paylode)
  File "/home/m0nd2y/.local/lib/python3.8/site-packages/flask_restx/api.py", line 285, in __getattr__
    raise AttributeError("Api does not have {0} attribute".format(name))
AttributeError: Api does not have paylode attribute
127.0.0.1 - - [13/Jun/2023 10:02:55] "POST /SearchDep/ HTTP/1.1" 500 -
Traceback (most recent call last):
  File "/home/m0nd2y/.local/lib/python3.8/site-packages/flask_restx/api.py", line 283, in __getattr__
    return getattr(self.default_namespace, name)
AttributeError: 'Namespace' object has no attribute 'paylode'

During handling of the above exception, another exception occurred:

Traceback (most recent call last):
  File "/home/m0nd2y/.local/lib/python3.8/site-packages/flask/app.py", line 2213, in __call__
    return self.wsgi_app(environ, start_response)
  File "/home/m0nd2y/.local/lib/python3.8/site-packages/flask/app.py", line 2193, in wsgi_app
    response = self.handle_exception(e)
  File "/home/m0nd2y/.local/lib/python3.8/site-packages/flask_restx/api.py", line 673, in error_router
    return original_handler(f)
  File "/home/m0nd2y/.local/lib/python3.8/site-packages/flask_restx/api.py", line 671, in error_router
    return self.handle_error(e)
  File "/home/m0nd2y/.local/lib/python3.8/site-packages/flask/app.py", line 2190, in wsgi_app
    response = self.full_dispatch_request()
  File "/home/m0nd2y/.local/lib/python3.8/site-packages/flask/app.py", line 1486, in full_dispatch_request
    rv = self.handle_user_exception(e)
  File "/home/m0nd2y/.local/lib/python3.8/site-packages/flask_restx/api.py", line 673, in error_router
    return original_handler(f)
  File "/home/m0nd2y/.local/lib/python3.8/site-packages/flask_restx/api.py", line 671, in error_router
    return self.handle_error(e)
  File "/home/m0nd2y/.local/lib/python3.8/site-packages/flask/app.py", line 1484, in full_dispatch_request
    rv = self.dispatch_request()
  File "/home/m0nd2y/.local/lib/python3.8/site-packages/flask/app.py", line 1469, in dispatch_request
    return self.ensure_sync(self.view_functions[rule.endpoint])(**view_args)
  File "/home/m0nd2y/.local/lib/python3.8/site-packages/flask_restx/api.py", line 404, in wrapper
    resp = resource(*args, **kwargs)
  File "/home/m0nd2y/.local/lib/python3.8/site-packages/flask/views.py", line 109, in view
    return current_app.ensure_sync(self.dispatch_request)(**kwargs)
  File "/home/m0nd2y/.local/lib/python3.8/site-packages/flask_restx/resource.py", line 46, in dispatch_request
    resp = meth(*args, **kwargs)
  File "/home/m0nd2y/SearchVuln/app.py", line 56, in post
    print(api.paylode)
  File "/home/m0nd2y/.local/lib/python3.8/site-packages/flask_restx/api.py", line 285, in __getattr__
    raise AttributeError("Api does not have {0} attribute".format(name))
AttributeError: Api does not have paylode attribute
127.0.0.1 - - [13/Jun/2023 10:03:25] "POST /SearchDep/ HTTP/1.1" 500 -
Traceback (most recent call last):
  File "/home/m0nd2y/.local/lib/python3.8/site-packages/flask_restx/api.py", line 283, in __getattr__
    return getattr(self.default_namespace, name)
AttributeError: 'Namespace' object has no attribute 'paylode'

During handling of the above exception, another exception occurred:

Traceback (most recent call last):
  File "/home/m0nd2y/.local/lib/python3.8/site-packages/flask/app.py", line 2213, in __call__
    return self.wsgi_app(environ, start_response)
  File "/home/m0nd2y/.local/lib/python3.8/site-packages/flask/app.py", line 2193, in wsgi_app
    response = self.handle_exception(e)
  File "/home/m0nd2y/.local/lib/python3.8/site-packages/flask_restx/api.py", line 673, in error_router
    return original_handler(f)
  File "/home/m0nd2y/.local/lib/python3.8/site-packages/flask_restx/api.py", line 671, in error_router
    return self.handle_error(e)
  File "/home/m0nd2y/.local/lib/python3.8/site-packages/flask/app.py", line 2190, in wsgi_app
    response = self.full_dispatch_request()
  File "/home/m0nd2y/.local/lib/python3.8/site-packages/flask/app.py", line 1486, in full_dispatch_request
    rv = self.handle_user_exception(e)
  File "/home/m0nd2y/.local/lib/python3.8/site-packages/flask_restx/api.py", line 673, in error_router
    return original_handler(f)
  File "/home/m0nd2y/.local/lib/python3.8/site-packages/flask_restx/api.py", line 671, in error_router
    return self.handle_error(e)
  File "/home/m0nd2y/.local/lib/python3.8/site-packages/flask/app.py", line 1484, in full_dispatch_request
    rv = self.dispatch_request()
  File "/home/m0nd2y/.local/lib/python3.8/site-packages/flask/app.py", line 1469, in dispatch_request
    return self.ensure_sync(self.view_functions[rule.endpoint])(**view_args)
  File "/home/m0nd2y/.local/lib/python3.8/site-packages/flask_restx/api.py", line 404, in wrapper
    resp = resource(*args, **kwargs)
  File "/home/m0nd2y/.local/lib/python3.8/site-packages/flask/views.py", line 109, in view
    return current_app.ensure_sync(self.dispatch_request)(**kwargs)
  File "/home/m0nd2y/.local/lib/python3.8/site-packages/flask_restx/resource.py", line 46, in dispatch_request
    resp = meth(*args, **kwargs)
  File "/home/m0nd2y/SearchVuln/app.py", line 56, in post
    print(api.paylode)
  File "/home/m0nd2y/.local/lib/python3.8/site-packages/flask_restx/api.py", line 285, in __getattr__
    raise AttributeError("Api does not have {0} attribute".format(name))
AttributeError: Api does not have paylode attribute
61.72.167.71 - - [13/Jun/2023 10:04:05] "GET /api-docs HTTP/1.1" 200 -
61.72.167.71 - - [13/Jun/2023 10:04:06] "GET /swaggerui/droid-sans.css HTTP/1.1" 304 -
61.72.167.71 - - [13/Jun/2023 10:04:06] "GET /swaggerui/swagger-ui.css HTTP/1.1" 304 -
61.72.167.71 - - [13/Jun/2023 10:04:06] "GET /swaggerui/swagger-ui-bundle.js HTTP/1.1" 304 -
61.72.167.71 - - [13/Jun/2023 10:04:06] "GET /swaggerui/swagger-ui-standalone-preset.js HTTP/1.1" 304 -
61.72.167.71 - - [13/Jun/2023 10:04:06] "GET /swagger.json HTTP/1.1" 200 -
61.72.167.71 - - [13/Jun/2023 10:04:06] "GET /swaggerui/favicon-32x32.png HTTP/1.1" 304 -
127.0.0.1 - - [13/Jun/2023 10:24:57] "POST /SearchDep/ HTTP/1.1" 500 -
Traceback (most recent call last):
  File "/home/m0nd2y/.local/lib/python3.8/site-packages/flask_restx/api.py", line 283, in __getattr__
    return getattr(self.default_namespace, name)
AttributeError: 'Namespace' object has no attribute 'paylode'

During handling of the above exception, another exception occurred:

Traceback (most recent call last):
  File "/home/m0nd2y/.local/lib/python3.8/site-packages/flask/app.py", line 2213, in __call__
    return self.wsgi_app(environ, start_response)
  File "/home/m0nd2y/.local/lib/python3.8/site-packages/flask/app.py", line 2193, in wsgi_app
    response = self.handle_exception(e)
  File "/home/m0nd2y/.local/lib/python3.8/site-packages/flask_restx/api.py", line 673, in error_router
    return original_handler(f)
  File "/home/m0nd2y/.local/lib/python3.8/site-packages/flask_restx/api.py", line 671, in error_router
    return self.handle_error(e)
  File "/home/m0nd2y/.local/lib/python3.8/site-packages/flask/app.py", line 2190, in wsgi_app
    response = self.full_dispatch_request()
  File "/home/m0nd2y/.local/lib/python3.8/site-packages/flask/app.py", line 1486, in full_dispatch_request
    rv = self.handle_user_exception(e)
  File "/home/m0nd2y/.local/lib/python3.8/site-packages/flask_restx/api.py", line 673, in error_router
    return original_handler(f)
  File "/home/m0nd2y/.local/lib/python3.8/site-packages/flask_restx/api.py", line 671, in error_router
    return self.handle_error(e)
  File "/home/m0nd2y/.local/lib/python3.8/site-packages/flask/app.py", line 1484, in full_dispatch_request
    rv = self.dispatch_request()
  File "/home/m0nd2y/.local/lib/python3.8/site-packages/flask/app.py", line 1469, in dispatch_request
    return self.ensure_sync(self.view_functions[rule.endpoint])(**view_args)
  File "/home/m0nd2y/.local/lib/python3.8/site-packages/flask_restx/api.py", line 404, in wrapper
    resp = resource(*args, **kwargs)
  File "/home/m0nd2y/.local/lib/python3.8/site-packages/flask/views.py", line 109, in view
    return current_app.ensure_sync(self.dispatch_request)(**kwargs)
  File "/home/m0nd2y/.local/lib/python3.8/site-packages/flask_restx/resource.py", line 46, in dispatch_request
    resp = meth(*args, **kwargs)
  File "/home/m0nd2y/SearchVuln/app.py", line 56, in post
    print(api.paylode)
  File "/home/m0nd2y/.local/lib/python3.8/site-packages/flask_restx/api.py", line 285, in __getattr__
    raise AttributeError("Api does not have {0} attribute".format(name))
AttributeError: Api does not have paylode attribute
127.0.0.1 - - [13/Jun/2023 10:26:47] "POST /SearchDep/ HTTP/1.1" 500 -
Traceback (most recent call last):
  File "/home/m0nd2y/.local/lib/python3.8/site-packages/flask_restx/api.py", line 283, in __getattr__
    return getattr(self.default_namespace, name)
AttributeError: 'Namespace' object has no attribute 'paylode'

During handling of the above exception, another exception occurred:

Traceback (most recent call last):
  File "/home/m0nd2y/.local/lib/python3.8/site-packages/flask/app.py", line 2213, in __call__
    return self.wsgi_app(environ, start_response)
  File "/home/m0nd2y/.local/lib/python3.8/site-packages/flask/app.py", line 2193, in wsgi_app
    response = self.handle_exception(e)
  File "/home/m0nd2y/.local/lib/python3.8/site-packages/flask_restx/api.py", line 673, in error_router
    return original_handler(f)
  File "/home/m0nd2y/.local/lib/python3.8/site-packages/flask_restx/api.py", line 671, in error_router
    return self.handle_error(e)
  File "/home/m0nd2y/.local/lib/python3.8/site-packages/flask/app.py", line 2190, in wsgi_app
    response = self.full_dispatch_request()
  File "/home/m0nd2y/.local/lib/python3.8/site-packages/flask/app.py", line 1486, in full_dispatch_request
    rv = self.handle_user_exception(e)
  File "/home/m0nd2y/.local/lib/python3.8/site-packages/flask_restx/api.py", line 673, in error_router
    return original_handler(f)
  File "/home/m0nd2y/.local/lib/python3.8/site-packages/flask_restx/api.py", line 671, in error_router
    return self.handle_error(e)
  File "/home/m0nd2y/.local/lib/python3.8/site-packages/flask/app.py", line 1484, in full_dispatch_request
    rv = self.dispatch_request()
  File "/home/m0nd2y/.local/lib/python3.8/site-packages/flask/app.py", line 1469, in dispatch_request
    return self.ensure_sync(self.view_functions[rule.endpoint])(**view_args)
  File "/home/m0nd2y/.local/lib/python3.8/site-packages/flask_restx/api.py", line 404, in wrapper
    resp = resource(*args, **kwargs)
  File "/home/m0nd2y/.local/lib/python3.8/site-packages/flask/views.py", line 109, in view
    return current_app.ensure_sync(self.dispatch_request)(**kwargs)
  File "/home/m0nd2y/.local/lib/python3.8/site-packages/flask_restx/resource.py", line 46, in dispatch_request
    resp = meth(*args, **kwargs)
  File "/home/m0nd2y/SearchVuln/app.py", line 56, in post
    print(api.paylode)
  File "/home/m0nd2y/.local/lib/python3.8/site-packages/flask_restx/api.py", line 285, in __getattr__
    raise AttributeError("Api does not have {0} attribute".format(name))
AttributeError: Api does not have paylode attribute
127.0.0.1 - - [13/Jun/2023 10:26:47] "POST /SearchVuln/ HTTP/1.1" 200 -
127.0.0.1 - - [13/Jun/2023 10:26:47] "POST /SearchVuln/ HTTP/1.1" 200 -
127.0.0.1 - - [13/Jun/2023 10:26:47] "POST /SearchVuln/ HTTP/1.1" 200 -
127.0.0.1 - - [13/Jun/2023 10:26:48] "POST /SearchVuln/ HTTP/1.1" 200 -
127.0.0.1 - - [13/Jun/2023 10:27:29] "POST /SearchDep/ HTTP/1.1" 500 -
Traceback (most recent call last):
  File "/home/m0nd2y/.local/lib/python3.8/site-packages/flask_restx/api.py", line 283, in __getattr__
    return getattr(self.default_namespace, name)
AttributeError: 'Namespace' object has no attribute 'paylode'

During handling of the above exception, another exception occurred:

Traceback (most recent call last):
  File "/home/m0nd2y/.local/lib/python3.8/site-packages/flask/app.py", line 2213, in __call__
    return self.wsgi_app(environ, start_response)
  File "/home/m0nd2y/.local/lib/python3.8/site-packages/flask/app.py", line 2193, in wsgi_app
    response = self.handle_exception(e)
  File "/home/m0nd2y/.local/lib/python3.8/site-packages/flask_restx/api.py", line 673, in error_router
    return original_handler(f)
  File "/home/m0nd2y/.local/lib/python3.8/site-packages/flask_restx/api.py", line 671, in error_router
    return self.handle_error(e)
  File "/home/m0nd2y/.local/lib/python3.8/site-packages/flask/app.py", line 2190, in wsgi_app
    response = self.full_dispatch_request()
  File "/home/m0nd2y/.local/lib/python3.8/site-packages/flask/app.py", line 1486, in full_dispatch_request
    rv = self.handle_user_exception(e)
  File "/home/m0nd2y/.local/lib/python3.8/site-packages/flask_restx/api.py", line 673, in error_router
    return original_handler(f)
  File "/home/m0nd2y/.local/lib/python3.8/site-packages/flask_restx/api.py", line 671, in error_router
    return self.handle_error(e)
  File "/home/m0nd2y/.local/lib/python3.8/site-packages/flask/app.py", line 1484, in full_dispatch_request
    rv = self.dispatch_request()
  File "/home/m0nd2y/.local/lib/python3.8/site-packages/flask/app.py", line 1469, in dispatch_request
    return self.ensure_sync(self.view_functions[rule.endpoint])(**view_args)
  File "/home/m0nd2y/.local/lib/python3.8/site-packages/flask_restx/api.py", line 404, in wrapper
    resp = resource(*args, **kwargs)
  File "/home/m0nd2y/.local/lib/python3.8/site-packages/flask/views.py", line 109, in view
    return current_app.ensure_sync(self.dispatch_request)(**kwargs)
  File "/home/m0nd2y/.local/lib/python3.8/site-packages/flask_restx/resource.py", line 46, in dispatch_request
    resp = meth(*args, **kwargs)
  File "/home/m0nd2y/SearchVuln/app.py", line 56, in post
    print(api.paylode)
  File "/home/m0nd2y/.local/lib/python3.8/site-packages/flask_restx/api.py", line 285, in __getattr__
    raise AttributeError("Api does not have {0} attribute".format(name))
AttributeError: Api does not have paylode attribute
127.0.0.1 - - [13/Jun/2023 10:27:30] "POST /SearchVuln/ HTTP/1.1" 200 -
127.0.0.1 - - [13/Jun/2023 10:27:30] "POST /SearchVuln/ HTTP/1.1" 200 -
127.0.0.1 - - [13/Jun/2023 10:27:30] "POST /SearchVuln/ HTTP/1.1" 200 -
127.0.0.1 - - [13/Jun/2023 10:27:30] "POST /SearchVuln/ HTTP/1.1" 200 -
127.0.0.1 - - [13/Jun/2023 10:27:39] "POST /SearchDep/ HTTP/1.1" 500 -
Traceback (most recent call last):
  File "/home/m0nd2y/.local/lib/python3.8/site-packages/flask_restx/api.py", line 283, in __getattr__
    return getattr(self.default_namespace, name)
AttributeError: 'Namespace' object has no attribute 'paylode'

During handling of the above exception, another exception occurred:

Traceback (most recent call last):
  File "/home/m0nd2y/.local/lib/python3.8/site-packages/flask/app.py", line 2213, in __call__
    return self.wsgi_app(environ, start_response)
  File "/home/m0nd2y/.local/lib/python3.8/site-packages/flask/app.py", line 2193, in wsgi_app
    response = self.handle_exception(e)
  File "/home/m0nd2y/.local/lib/python3.8/site-packages/flask_restx/api.py", line 673, in error_router
    return original_handler(f)
  File "/home/m0nd2y/.local/lib/python3.8/site-packages/flask_restx/api.py", line 671, in error_router
    return self.handle_error(e)
  File "/home/m0nd2y/.local/lib/python3.8/site-packages/flask/app.py", line 2190, in wsgi_app
    response = self.full_dispatch_request()
  File "/home/m0nd2y/.local/lib/python3.8/site-packages/flask/app.py", line 1486, in full_dispatch_request
    rv = self.handle_user_exception(e)
  File "/home/m0nd2y/.local/lib/python3.8/site-packages/flask_restx/api.py", line 673, in error_router
    return original_handler(f)
  File "/home/m0nd2y/.local/lib/python3.8/site-packages/flask_restx/api.py", line 671, in error_router
    return self.handle_error(e)
  File "/home/m0nd2y/.local/lib/python3.8/site-packages/flask/app.py", line 1484, in full_dispatch_request
    rv = self.dispatch_request()
  File "/home/m0nd2y/.local/lib/python3.8/site-packages/flask/app.py", line 1469, in dispatch_request
    return self.ensure_sync(self.view_functions[rule.endpoint])(**view_args)
  File "/home/m0nd2y/.local/lib/python3.8/site-packages/flask_restx/api.py", line 404, in wrapper
    resp = resource(*args, **kwargs)
  File "/home/m0nd2y/.local/lib/python3.8/site-packages/flask/views.py", line 109, in view
    return current_app.ensure_sync(self.dispatch_request)(**kwargs)
  File "/home/m0nd2y/.local/lib/python3.8/site-packages/flask_restx/resource.py", line 46, in dispatch_request
    resp = meth(*args, **kwargs)
  File "/home/m0nd2y/SearchVuln/app.py", line 56, in post
    print(api.paylode)
  File "/home/m0nd2y/.local/lib/python3.8/site-packages/flask_restx/api.py", line 285, in __getattr__
    raise AttributeError("Api does not have {0} attribute".format(name))
AttributeError: Api does not have paylode attribute
127.0.0.1 - - [13/Jun/2023 10:27:39] "POST /SearchVuln/ HTTP/1.1" 200 -
127.0.0.1 - - [13/Jun/2023 10:27:39] "POST /SearchVuln/ HTTP/1.1" 200 -
127.0.0.1 - - [13/Jun/2023 10:27:39] "POST /SearchVuln/ HTTP/1.1" 200 -
127.0.0.1 - - [13/Jun/2023 10:27:40] "POST /SearchVuln/ HTTP/1.1" 200 -
127.0.0.1 - - [13/Jun/2023 10:27:53] "POST /SearchVuln/ HTTP/1.1" 200 -
127.0.0.1 - - [13/Jun/2023 10:27:53] "POST /SearchDep/ HTTP/1.1" 500 -
Traceback (most recent call last):
  File "/home/m0nd2y/.local/lib/python3.8/site-packages/flask_restx/api.py", line 283, in __getattr__
    return getattr(self.default_namespace, name)
AttributeError: 'Namespace' object has no attribute 'paylode'

During handling of the above exception, another exception occurred:

Traceback (most recent call last):
  File "/home/m0nd2y/.local/lib/python3.8/site-packages/flask/app.py", line 2213, in __call__
    return self.wsgi_app(environ, start_response)
  File "/home/m0nd2y/.local/lib/python3.8/site-packages/flask/app.py", line 2193, in wsgi_app
    response = self.handle_exception(e)
  File "/home/m0nd2y/.local/lib/python3.8/site-packages/flask_restx/api.py", line 673, in error_router
    return original_handler(f)
  File "/home/m0nd2y/.local/lib/python3.8/site-packages/flask_restx/api.py", line 671, in error_router
    return self.handle_error(e)
  File "/home/m0nd2y/.local/lib/python3.8/site-packages/flask/app.py", line 2190, in wsgi_app
    response = self.full_dispatch_request()
  File "/home/m0nd2y/.local/lib/python3.8/site-packages/flask/app.py", line 1486, in full_dispatch_request
    rv = self.handle_user_exception(e)
  File "/home/m0nd2y/.local/lib/python3.8/site-packages/flask_restx/api.py", line 673, in error_router
    return original_handler(f)
  File "/home/m0nd2y/.local/lib/python3.8/site-packages/flask_restx/api.py", line 671, in error_router
    return self.handle_error(e)
  File "/home/m0nd2y/.local/lib/python3.8/site-packages/flask/app.py", line 1484, in full_dispatch_request
    rv = self.dispatch_request()
  File "/home/m0nd2y/.local/lib/python3.8/site-packages/flask/app.py", line 1469, in dispatch_request
    return self.ensure_sync(self.view_functions[rule.endpoint])(**view_args)
  File "/home/m0nd2y/.local/lib/python3.8/site-packages/flask_restx/api.py", line 404, in wrapper
    resp = resource(*args, **kwargs)
  File "/home/m0nd2y/.local/lib/python3.8/site-packages/flask/views.py", line 109, in view
    return current_app.ensure_sync(self.dispatch_request)(**kwargs)
  File "/home/m0nd2y/.local/lib/python3.8/site-packages/flask_restx/resource.py", line 46, in dispatch_request
    resp = meth(*args, **kwargs)
  File "/home/m0nd2y/SearchVuln/app.py", line 56, in post
    print(api.paylode)
  File "/home/m0nd2y/.local/lib/python3.8/site-packages/flask_restx/api.py", line 285, in __getattr__
    raise AttributeError("Api does not have {0} attribute".format(name))
AttributeError: Api does not have paylode attribute
127.0.0.1 - - [13/Jun/2023 10:27:53] "POST /SearchVuln/ HTTP/1.1" 200 -
127.0.0.1 - - [13/Jun/2023 10:27:53] "POST /SearchVuln/ HTTP/1.1" 200 -
127.0.0.1 - - [13/Jun/2023 10:27:53] "POST /SearchVuln/ HTTP/1.1" 200 -
127.0.0.1 - - [13/Jun/2023 10:27:53] "POST /SearchVuln/ HTTP/1.1" 200 -
127.0.0.1 - - [13/Jun/2023 10:27:54] "POST /SearchDep/ HTTP/1.1" 500 -
Traceback (most recent call last):
  File "/home/m0nd2y/.local/lib/python3.8/site-packages/flask_restx/api.py", line 283, in __getattr__
    return getattr(self.default_namespace, name)
AttributeError: 'Namespace' object has no attribute 'paylode'

During handling of the above exception, another exception occurred:

Traceback (most recent call last):
  File "/home/m0nd2y/.local/lib/python3.8/site-packages/flask/app.py", line 2213, in __call__
    return self.wsgi_app(environ, start_response)
  File "/home/m0nd2y/.local/lib/python3.8/site-packages/flask/app.py", line 2193, in wsgi_app
    response = self.handle_exception(e)
  File "/home/m0nd2y/.local/lib/python3.8/site-packages/flask_restx/api.py", line 673, in error_router
    return original_handler(f)
  File "/home/m0nd2y/.local/lib/python3.8/site-packages/flask_restx/api.py", line 671, in error_router
    return self.handle_error(e)
  File "/home/m0nd2y/.local/lib/python3.8/site-packages/flask/app.py", line 2190, in wsgi_app
    response = self.full_dispatch_request()
  File "/home/m0nd2y/.local/lib/python3.8/site-packages/flask/app.py", line 1486, in full_dispatch_request
    rv = self.handle_user_exception(e)
  File "/home/m0nd2y/.local/lib/python3.8/site-packages/flask_restx/api.py", line 673, in error_router
    return original_handler(f)
  File "/home/m0nd2y/.local/lib/python3.8/site-packages/flask_restx/api.py", line 671, in error_router
    return self.handle_error(e)
  File "/home/m0nd2y/.local/lib/python3.8/site-packages/flask/app.py", line 1484, in full_dispatch_request
    rv = self.dispatch_request()
  File "/home/m0nd2y/.local/lib/python3.8/site-packages/flask/app.py", line 1469, in dispatch_request
    return self.ensure_sync(self.view_functions[rule.endpoint])(**view_args)
  File "/home/m0nd2y/.local/lib/python3.8/site-packages/flask_restx/api.py", line 404, in wrapper
    resp = resource(*args, **kwargs)
  File "/home/m0nd2y/.local/lib/python3.8/site-packages/flask/views.py", line 109, in view
    return current_app.ensure_sync(self.dispatch_request)(**kwargs)
  File "/home/m0nd2y/.local/lib/python3.8/site-packages/flask_restx/resource.py", line 46, in dispatch_request
    resp = meth(*args, **kwargs)
  File "/home/m0nd2y/SearchVuln/app.py", line 56, in post
    print(api.paylode)
  File "/home/m0nd2y/.local/lib/python3.8/site-packages/flask_restx/api.py", line 285, in __getattr__
    raise AttributeError("Api does not have {0} attribute".format(name))
AttributeError: Api does not have paylode attribute
127.0.0.1 - - [13/Jun/2023 10:27:54] "POST /SearchVuln/ HTTP/1.1" 200 -
127.0.0.1 - - [13/Jun/2023 10:27:54] "POST /SearchVuln/ HTTP/1.1" 200 -
127.0.0.1 - - [13/Jun/2023 10:27:54] "POST /SearchVuln/ HTTP/1.1" 200 -
127.0.0.1 - - [13/Jun/2023 10:27:55] "POST /SearchDep/ HTTP/1.1" 500 -
Traceback (most recent call last):
  File "/home/m0nd2y/.local/lib/python3.8/site-packages/flask_restx/api.py", line 283, in __getattr__
    return getattr(self.default_namespace, name)
AttributeError: 'Namespace' object has no attribute 'paylode'

During handling of the above exception, another exception occurred:

Traceback (most recent call last):
  File "/home/m0nd2y/.local/lib/python3.8/site-packages/flask/app.py", line 2213, in __call__
    return self.wsgi_app(environ, start_response)
  File "/home/m0nd2y/.local/lib/python3.8/site-packages/flask/app.py", line 2193, in wsgi_app
    response = self.handle_exception(e)
  File "/home/m0nd2y/.local/lib/python3.8/site-packages/flask_restx/api.py", line 673, in error_router
    return original_handler(f)
  File "/home/m0nd2y/.local/lib/python3.8/site-packages/flask_restx/api.py", line 671, in error_router
    return self.handle_error(e)
  File "/home/m0nd2y/.local/lib/python3.8/site-packages/flask/app.py", line 2190, in wsgi_app
    response = self.full_dispatch_request()
  File "/home/m0nd2y/.local/lib/python3.8/site-packages/flask/app.py", line 1486, in full_dispatch_request
    rv = self.handle_user_exception(e)
  File "/home/m0nd2y/.local/lib/python3.8/site-packages/flask_restx/api.py", line 673, in error_router
    return original_handler(f)
  File "/home/m0nd2y/.local/lib/python3.8/site-packages/flask_restx/api.py", line 671, in error_router
    return self.handle_error(e)
  File "/home/m0nd2y/.local/lib/python3.8/site-packages/flask/app.py", line 1484, in full_dispatch_request
    rv = self.dispatch_request()
  File "/home/m0nd2y/.local/lib/python3.8/site-packages/flask/app.py", line 1469, in dispatch_request
    return self.ensure_sync(self.view_functions[rule.endpoint])(**view_args)
  File "/home/m0nd2y/.local/lib/python3.8/site-packages/flask_restx/api.py", line 404, in wrapper
    resp = resource(*args, **kwargs)
  File "/home/m0nd2y/.local/lib/python3.8/site-packages/flask/views.py", line 109, in view
    return current_app.ensure_sync(self.dispatch_request)(**kwargs)
  File "/home/m0nd2y/.local/lib/python3.8/site-packages/flask_restx/resource.py", line 46, in dispatch_request
    resp = meth(*args, **kwargs)
  File "/home/m0nd2y/SearchVuln/app.py", line 56, in post
    print(api.paylode)
  File "/home/m0nd2y/.local/lib/python3.8/site-packages/flask_restx/api.py", line 285, in __getattr__
    raise AttributeError("Api does not have {0} attribute".format(name))
AttributeError: Api does not have paylode attribute
127.0.0.1 - - [13/Jun/2023 10:27:56] "POST /SearchVuln/ HTTP/1.1" 200 -
127.0.0.1 - - [13/Jun/2023 10:27:56] "POST /SearchVuln/ HTTP/1.1" 200 -
127.0.0.1 - - [13/Jun/2023 10:27:56] "POST /SearchVuln/ HTTP/1.1" 200 -
127.0.0.1 - - [13/Jun/2023 10:27:56] "POST /SearchVuln/ HTTP/1.1" 200 -
127.0.0.1 - - [13/Jun/2023 10:28:12] "POST /SearchDep/ HTTP/1.1" 500 -
Traceback (most recent call last):
  File "/home/m0nd2y/.local/lib/python3.8/site-packages/flask_restx/api.py", line 283, in __getattr__
    return getattr(self.default_namespace, name)
AttributeError: 'Namespace' object has no attribute 'paylode'

During handling of the above exception, another exception occurred:

Traceback (most recent call last):
  File "/home/m0nd2y/.local/lib/python3.8/site-packages/flask/app.py", line 2213, in __call__
    return self.wsgi_app(environ, start_response)
  File "/home/m0nd2y/.local/lib/python3.8/site-packages/flask/app.py", line 2193, in wsgi_app
    response = self.handle_exception(e)
  File "/home/m0nd2y/.local/lib/python3.8/site-packages/flask_restx/api.py", line 673, in error_router
    return original_handler(f)
  File "/home/m0nd2y/.local/lib/python3.8/site-packages/flask_restx/api.py", line 671, in error_router
    return self.handle_error(e)
  File "/home/m0nd2y/.local/lib/python3.8/site-packages/flask/app.py", line 2190, in wsgi_app
    response = self.full_dispatch_request()
  File "/home/m0nd2y/.local/lib/python3.8/site-packages/flask/app.py", line 1486, in full_dispatch_request
    rv = self.handle_user_exception(e)
  File "/home/m0nd2y/.local/lib/python3.8/site-packages/flask_restx/api.py", line 673, in error_router
    return original_handler(f)
  File "/home/m0nd2y/.local/lib/python3.8/site-packages/flask_restx/api.py", line 671, in error_router
    return self.handle_error(e)
  File "/home/m0nd2y/.local/lib/python3.8/site-packages/flask/app.py", line 1484, in full_dispatch_request
    rv = self.dispatch_request()
  File "/home/m0nd2y/.local/lib/python3.8/site-packages/flask/app.py", line 1469, in dispatch_request
    return self.ensure_sync(self.view_functions[rule.endpoint])(**view_args)
  File "/home/m0nd2y/.local/lib/python3.8/site-packages/flask_restx/api.py", line 404, in wrapper
    resp = resource(*args, **kwargs)
  File "/home/m0nd2y/.local/lib/python3.8/site-packages/flask/views.py", line 109, in view
    return current_app.ensure_sync(self.dispatch_request)(**kwargs)
  File "/home/m0nd2y/.local/lib/python3.8/site-packages/flask_restx/resource.py", line 46, in dispatch_request
    resp = meth(*args, **kwargs)
  File "/home/m0nd2y/SearchVuln/app.py", line 56, in post
    print(api.paylode)
  File "/home/m0nd2y/.local/lib/python3.8/site-packages/flask_restx/api.py", line 285, in __getattr__
    raise AttributeError("Api does not have {0} attribute".format(name))
AttributeError: Api does not have paylode attribute
127.0.0.1 - - [13/Jun/2023 10:28:13] "POST /SearchVuln/ HTTP/1.1" 200 -
127.0.0.1 - - [13/Jun/2023 10:28:13] "POST /SearchVuln/ HTTP/1.1" 200 -
127.0.0.1 - - [13/Jun/2023 10:28:13] "POST /SearchVuln/ HTTP/1.1" 200 -
127.0.0.1 - - [13/Jun/2023 10:28:13] "POST /SearchVuln/ HTTP/1.1" 200 -
219.250.39.216 - - [13/Jun/2023 12:00:51] "GET /swaggerui/droid-sans.css HTTP/1.1" 304 -
219.250.39.216 - - [13/Jun/2023 12:00:51] "GET /swaggerui/swagger-ui.css HTTP/1.1" 304 -
219.250.39.216 - - [13/Jun/2023 12:00:51] "GET /swaggerui/swagger-ui-bundle.js HTTP/1.1" 304 -
219.250.39.216 - - [13/Jun/2023 12:00:51] "GET /swaggerui/swagger-ui-standalone-preset.js HTTP/1.1" 304 -
219.250.39.216 - - [13/Jun/2023 12:00:51] "GET /swagger.json HTTP/1.1" 200 -
127.0.0.1 - - [14/Jun/2023 05:35:05] "POST /SearchDep/ HTTP/1.1" 500 -
Traceback (most recent call last):
  File "/home/m0nd2y/.local/lib/python3.8/site-packages/flask_restx/api.py", line 283, in __getattr__
    return getattr(self.default_namespace, name)
AttributeError: 'Namespace' object has no attribute 'paylode'

During handling of the above exception, another exception occurred:

Traceback (most recent call last):
  File "/home/m0nd2y/.local/lib/python3.8/site-packages/flask/app.py", line 2213, in __call__
    return self.wsgi_app(environ, start_response)
  File "/home/m0nd2y/.local/lib/python3.8/site-packages/flask/app.py", line 2193, in wsgi_app
    response = self.handle_exception(e)
  File "/home/m0nd2y/.local/lib/python3.8/site-packages/flask_restx/api.py", line 673, in error_router
    return original_handler(f)
  File "/home/m0nd2y/.local/lib/python3.8/site-packages/flask_restx/api.py", line 671, in error_router
    return self.handle_error(e)
  File "/home/m0nd2y/.local/lib/python3.8/site-packages/flask/app.py", line 2190, in wsgi_app
    response = self.full_dispatch_request()
  File "/home/m0nd2y/.local/lib/python3.8/site-packages/flask/app.py", line 1486, in full_dispatch_request
    rv = self.handle_user_exception(e)
  File "/home/m0nd2y/.local/lib/python3.8/site-packages/flask_restx/api.py", line 673, in error_router
    return original_handler(f)
  File "/home/m0nd2y/.local/lib/python3.8/site-packages/flask_restx/api.py", line 671, in error_router
    return self.handle_error(e)
  File "/home/m0nd2y/.local/lib/python3.8/site-packages/flask/app.py", line 1484, in full_dispatch_request
    rv = self.dispatch_request()
  File "/home/m0nd2y/.local/lib/python3.8/site-packages/flask/app.py", line 1469, in dispatch_request
    return self.ensure_sync(self.view_functions[rule.endpoint])(**view_args)
  File "/home/m0nd2y/.local/lib/python3.8/site-packages/flask_restx/api.py", line 404, in wrapper
    resp = resource(*args, **kwargs)
  File "/home/m0nd2y/.local/lib/python3.8/site-packages/flask/views.py", line 109, in view
    return current_app.ensure_sync(self.dispatch_request)(**kwargs)
  File "/home/m0nd2y/.local/lib/python3.8/site-packages/flask_restx/resource.py", line 46, in dispatch_request
    resp = meth(*args, **kwargs)
  File "/home/m0nd2y/SearchVuln/app.py", line 56, in post
    print(api.paylode)
  File "/home/m0nd2y/.local/lib/python3.8/site-packages/flask_restx/api.py", line 285, in __getattr__
    raise AttributeError("Api does not have {0} attribute".format(name))
AttributeError: Api does not have paylode attribute
127.0.0.1 - - [14/Jun/2023 05:35:06] "POST /SearchVuln/ HTTP/1.1" 200 -
127.0.0.1 - - [14/Jun/2023 05:35:06] "POST /SearchVuln/ HTTP/1.1" 200 -
127.0.0.1 - - [14/Jun/2023 05:35:06] "POST /SearchVuln/ HTTP/1.1" 200 -
127.0.0.1 - - [14/Jun/2023 05:35:06] "POST /SearchVuln/ HTTP/1.1" 200 -
127.0.0.1 - - [14/Jun/2023 05:36:08] "POST /SearchDep/ HTTP/1.1" 500 -
Traceback (most recent call last):
  File "/home/m0nd2y/.local/lib/python3.8/site-packages/flask_restx/api.py", line 283, in __getattr__
    return getattr(self.default_namespace, name)
AttributeError: 'Namespace' object has no attribute 'paylode'

During handling of the above exception, another exception occurred:

Traceback (most recent call last):
  File "/home/m0nd2y/.local/lib/python3.8/site-packages/flask/app.py", line 2213, in __call__
    return self.wsgi_app(environ, start_response)
  File "/home/m0nd2y/.local/lib/python3.8/site-packages/flask/app.py", line 2193, in wsgi_app
    response = self.handle_exception(e)
  File "/home/m0nd2y/.local/lib/python3.8/site-packages/flask_restx/api.py", line 673, in error_router
    return original_handler(f)
  File "/home/m0nd2y/.local/lib/python3.8/site-packages/flask_restx/api.py", line 671, in error_router
    return self.handle_error(e)
  File "/home/m0nd2y/.local/lib/python3.8/site-packages/flask/app.py", line 2190, in wsgi_app
    response = self.full_dispatch_request()
  File "/home/m0nd2y/.local/lib/python3.8/site-packages/flask/app.py", line 1486, in full_dispatch_request
    rv = self.handle_user_exception(e)
  File "/home/m0nd2y/.local/lib/python3.8/site-packages/flask_restx/api.py", line 673, in error_router
    return original_handler(f)
  File "/home/m0nd2y/.local/lib/python3.8/site-packages/flask_restx/api.py", line 671, in error_router
    return self.handle_error(e)
  File "/home/m0nd2y/.local/lib/python3.8/site-packages/flask/app.py", line 1484, in full_dispatch_request
    rv = self.dispatch_request()
  File "/home/m0nd2y/.local/lib/python3.8/site-packages/flask/app.py", line 1469, in dispatch_request
    return self.ensure_sync(self.view_functions[rule.endpoint])(**view_args)
  File "/home/m0nd2y/.local/lib/python3.8/site-packages/flask_restx/api.py", line 404, in wrapper
    resp = resource(*args, **kwargs)
  File "/home/m0nd2y/.local/lib/python3.8/site-packages/flask/views.py", line 109, in view
    return current_app.ensure_sync(self.dispatch_request)(**kwargs)
  File "/home/m0nd2y/.local/lib/python3.8/site-packages/flask_restx/resource.py", line 46, in dispatch_request
    resp = meth(*args, **kwargs)
  File "/home/m0nd2y/SearchVuln/app.py", line 56, in post
    print(api.paylode)
  File "/home/m0nd2y/.local/lib/python3.8/site-packages/flask_restx/api.py", line 285, in __getattr__
    raise AttributeError("Api does not have {0} attribute".format(name))
AttributeError: Api does not have paylode attribute
127.0.0.1 - - [14/Jun/2023 05:36:08] "POST /SearchVuln/ HTTP/1.1" 200 -
127.0.0.1 - - [14/Jun/2023 05:36:08] "POST /SearchVuln/ HTTP/1.1" 200 -
127.0.0.1 - - [14/Jun/2023 05:36:08] "POST /SearchVuln/ HTTP/1.1" 200 -
127.0.0.1 - - [14/Jun/2023 05:36:08] "POST /SearchVuln/ HTTP/1.1" 200 -
127.0.0.1 - - [14/Jun/2023 05:36:10] "POST /SearchDep/ HTTP/1.1" 500 -
Traceback (most recent call last):
  File "/home/m0nd2y/.local/lib/python3.8/site-packages/flask_restx/api.py", line 283, in __getattr__
    return getattr(self.default_namespace, name)
AttributeError: 'Namespace' object has no attribute 'paylode'

During handling of the above exception, another exception occurred:

Traceback (most recent call last):
  File "/home/m0nd2y/.local/lib/python3.8/site-packages/flask/app.py", line 2213, in __call__
    return self.wsgi_app(environ, start_response)
  File "/home/m0nd2y/.local/lib/python3.8/site-packages/flask/app.py", line 2193, in wsgi_app
    response = self.handle_exception(e)
  File "/home/m0nd2y/.local/lib/python3.8/site-packages/flask_restx/api.py", line 673, in error_router
    return original_handler(f)
  File "/home/m0nd2y/.local/lib/python3.8/site-packages/flask_restx/api.py", line 671, in error_router
    return self.handle_error(e)
  File "/home/m0nd2y/.local/lib/python3.8/site-packages/flask/app.py", line 2190, in wsgi_app
    response = self.full_dispatch_request()
  File "/home/m0nd2y/.local/lib/python3.8/site-packages/flask/app.py", line 1486, in full_dispatch_request
    rv = self.handle_user_exception(e)
  File "/home/m0nd2y/.local/lib/python3.8/site-packages/flask_restx/api.py", line 673, in error_router
    return original_handler(f)
  File "/home/m0nd2y/.local/lib/python3.8/site-packages/flask_restx/api.py", line 671, in error_router
    return self.handle_error(e)
  File "/home/m0nd2y/.local/lib/python3.8/site-packages/flask/app.py", line 1484, in full_dispatch_request
    rv = self.dispatch_request()
  File "/home/m0nd2y/.local/lib/python3.8/site-packages/flask/app.py", line 1469, in dispatch_request
    return self.ensure_sync(self.view_functions[rule.endpoint])(**view_args)
  File "/home/m0nd2y/.local/lib/python3.8/site-packages/flask_restx/api.py", line 404, in wrapper
    resp = resource(*args, **kwargs)
  File "/home/m0nd2y/.local/lib/python3.8/site-packages/flask/views.py", line 109, in view
    return current_app.ensure_sync(self.dispatch_request)(**kwargs)
  File "/home/m0nd2y/.local/lib/python3.8/site-packages/flask_restx/resource.py", line 46, in dispatch_request
    resp = meth(*args, **kwargs)
  File "/home/m0nd2y/SearchVuln/app.py", line 56, in post
    print(api.paylode)
  File "/home/m0nd2y/.local/lib/python3.8/site-packages/flask_restx/api.py", line 285, in __getattr__
    raise AttributeError("Api does not have {0} attribute".format(name))
AttributeError: Api does not have paylode attribute
127.0.0.1 - - [14/Jun/2023 05:36:10] "POST /SearchVuln/ HTTP/1.1" 200 -
127.0.0.1 - - [14/Jun/2023 05:36:10] "POST /SearchVuln/ HTTP/1.1" 200 -
127.0.0.1 - - [14/Jun/2023 05:36:10] "POST /SearchVuln/ HTTP/1.1" 200 -
127.0.0.1 - - [14/Jun/2023 05:36:11] "POST /SearchVuln/ HTTP/1.1" 200 -
127.0.0.1 - - [14/Jun/2023 05:40:01] "POST /SearchDep/ HTTP/1.1" 500 -
Traceback (most recent call last):
  File "/home/m0nd2y/.local/lib/python3.8/site-packages/flask_restx/api.py", line 283, in __getattr__
    return getattr(self.default_namespace, name)
AttributeError: 'Namespace' object has no attribute 'paylode'

During handling of the above exception, another exception occurred:

Traceback (most recent call last):
  File "/home/m0nd2y/.local/lib/python3.8/site-packages/flask/app.py", line 2213, in __call__
    return self.wsgi_app(environ, start_response)
  File "/home/m0nd2y/.local/lib/python3.8/site-packages/flask/app.py", line 2193, in wsgi_app
    response = self.handle_exception(e)
  File "/home/m0nd2y/.local/lib/python3.8/site-packages/flask_restx/api.py", line 673, in error_router
    return original_handler(f)
  File "/home/m0nd2y/.local/lib/python3.8/site-packages/flask_restx/api.py", line 671, in error_router
    return self.handle_error(e)
  File "/home/m0nd2y/.local/lib/python3.8/site-packages/flask/app.py", line 2190, in wsgi_app
    response = self.full_dispatch_request()
  File "/home/m0nd2y/.local/lib/python3.8/site-packages/flask/app.py", line 1486, in full_dispatch_request
    rv = self.handle_user_exception(e)
  File "/home/m0nd2y/.local/lib/python3.8/site-packages/flask_restx/api.py", line 673, in error_router
    return original_handler(f)
  File "/home/m0nd2y/.local/lib/python3.8/site-packages/flask_restx/api.py", line 671, in error_router
    return self.handle_error(e)
  File "/home/m0nd2y/.local/lib/python3.8/site-packages/flask/app.py", line 1484, in full_dispatch_request
    rv = self.dispatch_request()
  File "/home/m0nd2y/.local/lib/python3.8/site-packages/flask/app.py", line 1469, in dispatch_request
    return self.ensure_sync(self.view_functions[rule.endpoint])(**view_args)
  File "/home/m0nd2y/.local/lib/python3.8/site-packages/flask_restx/api.py", line 404, in wrapper
    resp = resource(*args, **kwargs)
  File "/home/m0nd2y/.local/lib/python3.8/site-packages/flask/views.py", line 109, in view
    return current_app.ensure_sync(self.dispatch_request)(**kwargs)
  File "/home/m0nd2y/.local/lib/python3.8/site-packages/flask_restx/resource.py", line 46, in dispatch_request
    resp = meth(*args, **kwargs)
  File "/home/m0nd2y/SearchVuln/app.py", line 56, in post
    print(api.paylode)
  File "/home/m0nd2y/.local/lib/python3.8/site-packages/flask_restx/api.py", line 285, in __getattr__
    raise AttributeError("Api does not have {0} attribute".format(name))
AttributeError: Api does not have paylode attribute
127.0.0.1 - - [14/Jun/2023 05:40:01] "POST /SearchVuln/ HTTP/1.1" 200 -
127.0.0.1 - - [14/Jun/2023 05:40:01] "POST /SearchVuln/ HTTP/1.1" 200 -
127.0.0.1 - - [14/Jun/2023 05:40:01] "POST /SearchVuln/ HTTP/1.1" 200 -
127.0.0.1 - - [14/Jun/2023 05:40:01] "POST /SearchVuln/ HTTP/1.1" 200 -
127.0.0.1 - - [14/Jun/2023 05:40:22] "POST /SearchDep/ HTTP/1.1" 500 -
Traceback (most recent call last):
  File "/home/m0nd2y/.local/lib/python3.8/site-packages/flask_restx/api.py", line 283, in __getattr__
    return getattr(self.default_namespace, name)
AttributeError: 'Namespace' object has no attribute 'paylode'

During handling of the above exception, another exception occurred:

Traceback (most recent call last):
  File "/home/m0nd2y/.local/lib/python3.8/site-packages/flask/app.py", line 2213, in __call__
    return self.wsgi_app(environ, start_response)
  File "/home/m0nd2y/.local/lib/python3.8/site-packages/flask/app.py", line 2193, in wsgi_app
    response = self.handle_exception(e)
  File "/home/m0nd2y/.local/lib/python3.8/site-packages/flask_restx/api.py", line 673, in error_router
    return original_handler(f)
  File "/home/m0nd2y/.local/lib/python3.8/site-packages/flask_restx/api.py", line 671, in error_router
    return self.handle_error(e)
  File "/home/m0nd2y/.local/lib/python3.8/site-packages/flask/app.py", line 2190, in wsgi_app
    response = self.full_dispatch_request()
  File "/home/m0nd2y/.local/lib/python3.8/site-packages/flask/app.py", line 1486, in full_dispatch_request
    rv = self.handle_user_exception(e)
  File "/home/m0nd2y/.local/lib/python3.8/site-packages/flask_restx/api.py", line 673, in error_router
    return original_handler(f)
  File "/home/m0nd2y/.local/lib/python3.8/site-packages/flask_restx/api.py", line 671, in error_router
    return self.handle_error(e)
  File "/home/m0nd2y/.local/lib/python3.8/site-packages/flask/app.py", line 1484, in full_dispatch_request
    rv = self.dispatch_request()
  File "/home/m0nd2y/.local/lib/python3.8/site-packages/flask/app.py", line 1469, in dispatch_request
    return self.ensure_sync(self.view_functions[rule.endpoint])(**view_args)
  File "/home/m0nd2y/.local/lib/python3.8/site-packages/flask_restx/api.py", line 404, in wrapper
    resp = resource(*args, **kwargs)
  File "/home/m0nd2y/.local/lib/python3.8/site-packages/flask/views.py", line 109, in view
    return current_app.ensure_sync(self.dispatch_request)(**kwargs)
  File "/home/m0nd2y/.local/lib/python3.8/site-packages/flask_restx/resource.py", line 46, in dispatch_request
    resp = meth(*args, **kwargs)
  File "/home/m0nd2y/SearchVuln/app.py", line 56, in post
    print(api.paylode)
  File "/home/m0nd2y/.local/lib/python3.8/site-packages/flask_restx/api.py", line 285, in __getattr__
    raise AttributeError("Api does not have {0} attribute".format(name))
AttributeError: Api does not have paylode attribute
127.0.0.1 - - [14/Jun/2023 05:40:23] "POST /SearchVuln/ HTTP/1.1" 200 -
127.0.0.1 - - [14/Jun/2023 05:40:23] "POST /SearchVuln/ HTTP/1.1" 200 -
127.0.0.1 - - [14/Jun/2023 05:40:23] "POST /SearchVuln/ HTTP/1.1" 200 -
127.0.0.1 - - [14/Jun/2023 05:40:23] "POST /SearchVuln/ HTTP/1.1" 200 -
127.0.0.1 - - [14/Jun/2023 05:41:35] "POST /SearchDep/ HTTP/1.1" 500 -
Traceback (most recent call last):
  File "/home/m0nd2y/.local/lib/python3.8/site-packages/flask_restx/api.py", line 283, in __getattr__
    return getattr(self.default_namespace, name)
AttributeError: 'Namespace' object has no attribute 'paylode'

During handling of the above exception, another exception occurred:

Traceback (most recent call last):
  File "/home/m0nd2y/.local/lib/python3.8/site-packages/flask/app.py", line 2213, in __call__
    return self.wsgi_app(environ, start_response)
  File "/home/m0nd2y/.local/lib/python3.8/site-packages/flask/app.py", line 2193, in wsgi_app
    response = self.handle_exception(e)
  File "/home/m0nd2y/.local/lib/python3.8/site-packages/flask_restx/api.py", line 673, in error_router
    return original_handler(f)
  File "/home/m0nd2y/.local/lib/python3.8/site-packages/flask_restx/api.py", line 671, in error_router
    return self.handle_error(e)
  File "/home/m0nd2y/.local/lib/python3.8/site-packages/flask/app.py", line 2190, in wsgi_app
    response = self.full_dispatch_request()
  File "/home/m0nd2y/.local/lib/python3.8/site-packages/flask/app.py", line 1486, in full_dispatch_request
    rv = self.handle_user_exception(e)
  File "/home/m0nd2y/.local/lib/python3.8/site-packages/flask_restx/api.py", line 673, in error_router
    return original_handler(f)
  File "/home/m0nd2y/.local/lib/python3.8/site-packages/flask_restx/api.py", line 671, in error_router
    return self.handle_error(e)
  File "/home/m0nd2y/.local/lib/python3.8/site-packages/flask/app.py", line 1484, in full_dispatch_request
    rv = self.dispatch_request()
  File "/home/m0nd2y/.local/lib/python3.8/site-packages/flask/app.py", line 1469, in dispatch_request
    return self.ensure_sync(self.view_functions[rule.endpoint])(**view_args)
  File "/home/m0nd2y/.local/lib/python3.8/site-packages/flask_restx/api.py", line 404, in wrapper
    resp = resource(*args, **kwargs)
  File "/home/m0nd2y/.local/lib/python3.8/site-packages/flask/views.py", line 109, in view
    return current_app.ensure_sync(self.dispatch_request)(**kwargs)
  File "/home/m0nd2y/.local/lib/python3.8/site-packages/flask_restx/resource.py", line 46, in dispatch_request
    resp = meth(*args, **kwargs)
  File "/home/m0nd2y/SearchVuln/app.py", line 56, in post
    print(api.paylode)
  File "/home/m0nd2y/.local/lib/python3.8/site-packages/flask_restx/api.py", line 285, in __getattr__
    raise AttributeError("Api does not have {0} attribute".format(name))
AttributeError: Api does not have paylode attribute
127.0.0.1 - - [14/Jun/2023 05:41:36] "POST /SearchVuln/ HTTP/1.1" 200 -
127.0.0.1 - - [14/Jun/2023 05:41:36] "POST /SearchVuln/ HTTP/1.1" 200 -
127.0.0.1 - - [14/Jun/2023 05:41:36] "POST /SearchVuln/ HTTP/1.1" 200 -
127.0.0.1 - - [14/Jun/2023 05:41:36] "POST /SearchVuln/ HTTP/1.1" 200 -
127.0.0.1 - - [14/Jun/2023 05:42:34] "POST /SearchDep/ HTTP/1.1" 500 -
Traceback (most recent call last):
  File "/home/m0nd2y/.local/lib/python3.8/site-packages/flask_restx/api.py", line 283, in __getattr__
    return getattr(self.default_namespace, name)
AttributeError: 'Namespace' object has no attribute 'paylode'

During handling of the above exception, another exception occurred:

Traceback (most recent call last):
  File "/home/m0nd2y/.local/lib/python3.8/site-packages/flask/app.py", line 2213, in __call__
    return self.wsgi_app(environ, start_response)
  File "/home/m0nd2y/.local/lib/python3.8/site-packages/flask/app.py", line 2193, in wsgi_app
    response = self.handle_exception(e)
  File "/home/m0nd2y/.local/lib/python3.8/site-packages/flask_restx/api.py", line 673, in error_router
    return original_handler(f)
  File "/home/m0nd2y/.local/lib/python3.8/site-packages/flask_restx/api.py", line 671, in error_router
    return self.handle_error(e)
  File "/home/m0nd2y/.local/lib/python3.8/site-packages/flask/app.py", line 2190, in wsgi_app
    response = self.full_dispatch_request()
  File "/home/m0nd2y/.local/lib/python3.8/site-packages/flask/app.py", line 1486, in full_dispatch_request
    rv = self.handle_user_exception(e)
  File "/home/m0nd2y/.local/lib/python3.8/site-packages/flask_restx/api.py", line 673, in error_router
    return original_handler(f)
  File "/home/m0nd2y/.local/lib/python3.8/site-packages/flask_restx/api.py", line 671, in error_router
    return self.handle_error(e)
  File "/home/m0nd2y/.local/lib/python3.8/site-packages/flask/app.py", line 1484, in full_dispatch_request
    rv = self.dispatch_request()
  File "/home/m0nd2y/.local/lib/python3.8/site-packages/flask/app.py", line 1469, in dispatch_request
    return self.ensure_sync(self.view_functions[rule.endpoint])(**view_args)
  File "/home/m0nd2y/.local/lib/python3.8/site-packages/flask_restx/api.py", line 404, in wrapper
    resp = resource(*args, **kwargs)
  File "/home/m0nd2y/.local/lib/python3.8/site-packages/flask/views.py", line 109, in view
    return current_app.ensure_sync(self.dispatch_request)(**kwargs)
  File "/home/m0nd2y/.local/lib/python3.8/site-packages/flask_restx/resource.py", line 46, in dispatch_request
    resp = meth(*args, **kwargs)
  File "/home/m0nd2y/SearchVuln/app.py", line 56, in post
    print(api.paylode)
  File "/home/m0nd2y/.local/lib/python3.8/site-packages/flask_restx/api.py", line 285, in __getattr__
    raise AttributeError("Api does not have {0} attribute".format(name))
AttributeError: Api does not have paylode attribute
127.0.0.1 - - [14/Jun/2023 05:42:34] "POST /SearchVuln/ HTTP/1.1" 200 -
127.0.0.1 - - [14/Jun/2023 05:42:34] "POST /SearchVuln/ HTTP/1.1" 200 -
127.0.0.1 - - [14/Jun/2023 05:42:34] "POST /SearchVuln/ HTTP/1.1" 200 -
127.0.0.1 - - [14/Jun/2023 05:42:35] "POST /SearchVuln/ HTTP/1.1" 200 -
127.0.0.1 - - [14/Jun/2023 05:44:10] "POST /SearchDep/ HTTP/1.1" 500 -
Traceback (most recent call last):
  File "/home/m0nd2y/.local/lib/python3.8/site-packages/flask_restx/api.py", line 283, in __getattr__
    return getattr(self.default_namespace, name)
AttributeError: 'Namespace' object has no attribute 'paylode'

During handling of the above exception, another exception occurred:

Traceback (most recent call last):
  File "/home/m0nd2y/.local/lib/python3.8/site-packages/flask/app.py", line 2213, in __call__
    return self.wsgi_app(environ, start_response)
  File "/home/m0nd2y/.local/lib/python3.8/site-packages/flask/app.py", line 2193, in wsgi_app
    response = self.handle_exception(e)
  File "/home/m0nd2y/.local/lib/python3.8/site-packages/flask_restx/api.py", line 673, in error_router
    return original_handler(f)
  File "/home/m0nd2y/.local/lib/python3.8/site-packages/flask_restx/api.py", line 671, in error_router
    return self.handle_error(e)
  File "/home/m0nd2y/.local/lib/python3.8/site-packages/flask/app.py", line 2190, in wsgi_app
    response = self.full_dispatch_request()
  File "/home/m0nd2y/.local/lib/python3.8/site-packages/flask/app.py", line 1486, in full_dispatch_request
    rv = self.handle_user_exception(e)
  File "/home/m0nd2y/.local/lib/python3.8/site-packages/flask_restx/api.py", line 673, in error_router
    return original_handler(f)
  File "/home/m0nd2y/.local/lib/python3.8/site-packages/flask_restx/api.py", line 671, in error_router
    return self.handle_error(e)
  File "/home/m0nd2y/.local/lib/python3.8/site-packages/flask/app.py", line 1484, in full_dispatch_request
    rv = self.dispatch_request()
  File "/home/m0nd2y/.local/lib/python3.8/site-packages/flask/app.py", line 1469, in dispatch_request
    return self.ensure_sync(self.view_functions[rule.endpoint])(**view_args)
  File "/home/m0nd2y/.local/lib/python3.8/site-packages/flask_restx/api.py", line 404, in wrapper
    resp = resource(*args, **kwargs)
  File "/home/m0nd2y/.local/lib/python3.8/site-packages/flask/views.py", line 109, in view
    return current_app.ensure_sync(self.dispatch_request)(**kwargs)
  File "/home/m0nd2y/.local/lib/python3.8/site-packages/flask_restx/resource.py", line 46, in dispatch_request
    resp = meth(*args, **kwargs)
  File "/home/m0nd2y/SearchVuln/app.py", line 56, in post
    print(api.paylode)
  File "/home/m0nd2y/.local/lib/python3.8/site-packages/flask_restx/api.py", line 285, in __getattr__
    raise AttributeError("Api does not have {0} attribute".format(name))
AttributeError: Api does not have paylode attribute
127.0.0.1 - - [14/Jun/2023 05:44:10] "POST /SearchVuln/ HTTP/1.1" 200 -
127.0.0.1 - - [14/Jun/2023 05:44:10] "POST /SearchVuln/ HTTP/1.1" 200 -
127.0.0.1 - - [14/Jun/2023 05:44:10] "POST /SearchVuln/ HTTP/1.1" 200 -
127.0.0.1 - - [14/Jun/2023 05:44:10] "POST /SearchVuln/ HTTP/1.1" 200 -
127.0.0.1 - - [14/Jun/2023 05:44:42] "POST /SearchDep/ HTTP/1.1" 500 -
Traceback (most recent call last):
  File "/home/m0nd2y/.local/lib/python3.8/site-packages/flask_restx/api.py", line 283, in __getattr__
    return getattr(self.default_namespace, name)
AttributeError: 'Namespace' object has no attribute 'paylode'

During handling of the above exception, another exception occurred:

Traceback (most recent call last):
  File "/home/m0nd2y/.local/lib/python3.8/site-packages/flask/app.py", line 2213, in __call__
    return self.wsgi_app(environ, start_response)
  File "/home/m0nd2y/.local/lib/python3.8/site-packages/flask/app.py", line 2193, in wsgi_app
    response = self.handle_exception(e)
  File "/home/m0nd2y/.local/lib/python3.8/site-packages/flask_restx/api.py", line 673, in error_router
    return original_handler(f)
  File "/home/m0nd2y/.local/lib/python3.8/site-packages/flask_restx/api.py", line 671, in error_router
    return self.handle_error(e)
  File "/home/m0nd2y/.local/lib/python3.8/site-packages/flask/app.py", line 2190, in wsgi_app
    response = self.full_dispatch_request()
  File "/home/m0nd2y/.local/lib/python3.8/site-packages/flask/app.py", line 1486, in full_dispatch_request
    rv = self.handle_user_exception(e)
  File "/home/m0nd2y/.local/lib/python3.8/site-packages/flask_restx/api.py", line 673, in error_router
    return original_handler(f)
  File "/home/m0nd2y/.local/lib/python3.8/site-packages/flask_restx/api.py", line 671, in error_router
    return self.handle_error(e)
  File "/home/m0nd2y/.local/lib/python3.8/site-packages/flask/app.py", line 1484, in full_dispatch_request
    rv = self.dispatch_request()
  File "/home/m0nd2y/.local/lib/python3.8/site-packages/flask/app.py", line 1469, in dispatch_request
    return self.ensure_sync(self.view_functions[rule.endpoint])(**view_args)
  File "/home/m0nd2y/.local/lib/python3.8/site-packages/flask_restx/api.py", line 404, in wrapper
    resp = resource(*args, **kwargs)
  File "/home/m0nd2y/.local/lib/python3.8/site-packages/flask/views.py", line 109, in view
    return current_app.ensure_sync(self.dispatch_request)(**kwargs)
  File "/home/m0nd2y/.local/lib/python3.8/site-packages/flask_restx/resource.py", line 46, in dispatch_request
    resp = meth(*args, **kwargs)
  File "/home/m0nd2y/SearchVuln/app.py", line 56, in post
    print(api.paylode)
  File "/home/m0nd2y/.local/lib/python3.8/site-packages/flask_restx/api.py", line 285, in __getattr__
    raise AttributeError("Api does not have {0} attribute".format(name))
AttributeError: Api does not have paylode attribute
127.0.0.1 - - [14/Jun/2023 05:44:42] "POST /SearchVuln/ HTTP/1.1" 200 -
127.0.0.1 - - [14/Jun/2023 05:44:42] "POST /SearchVuln/ HTTP/1.1" 200 -
127.0.0.1 - - [14/Jun/2023 05:44:42] "POST /SearchVuln/ HTTP/1.1" 200 -
127.0.0.1 - - [14/Jun/2023 05:44:43] "POST /SearchVuln/ HTTP/1.1" 200 -
127.0.0.1 - - [14/Jun/2023 05:49:36] "POST /SearchDep/ HTTP/1.1" 500 -
Traceback (most recent call last):
  File "/home/m0nd2y/.local/lib/python3.8/site-packages/flask_restx/api.py", line 283, in __getattr__
    return getattr(self.default_namespace, name)
AttributeError: 'Namespace' object has no attribute 'paylode'

During handling of the above exception, another exception occurred:

Traceback (most recent call last):
  File "/home/m0nd2y/.local/lib/python3.8/site-packages/flask/app.py", line 2213, in __call__
    return self.wsgi_app(environ, start_response)
  File "/home/m0nd2y/.local/lib/python3.8/site-packages/flask/app.py", line 2193, in wsgi_app
    response = self.handle_exception(e)
  File "/home/m0nd2y/.local/lib/python3.8/site-packages/flask_restx/api.py", line 673, in error_router
    return original_handler(f)
  File "/home/m0nd2y/.local/lib/python3.8/site-packages/flask_restx/api.py", line 671, in error_router
    return self.handle_error(e)
  File "/home/m0nd2y/.local/lib/python3.8/site-packages/flask/app.py", line 2190, in wsgi_app
    response = self.full_dispatch_request()
  File "/home/m0nd2y/.local/lib/python3.8/site-packages/flask/app.py", line 1486, in full_dispatch_request
    rv = self.handle_user_exception(e)
  File "/home/m0nd2y/.local/lib/python3.8/site-packages/flask_restx/api.py", line 673, in error_router
    return original_handler(f)
  File "/home/m0nd2y/.local/lib/python3.8/site-packages/flask_restx/api.py", line 671, in error_router
    return self.handle_error(e)
  File "/home/m0nd2y/.local/lib/python3.8/site-packages/flask/app.py", line 1484, in full_dispatch_request
    rv = self.dispatch_request()
  File "/home/m0nd2y/.local/lib/python3.8/site-packages/flask/app.py", line 1469, in dispatch_request
    return self.ensure_sync(self.view_functions[rule.endpoint])(**view_args)
  File "/home/m0nd2y/.local/lib/python3.8/site-packages/flask_restx/api.py", line 404, in wrapper
    resp = resource(*args, **kwargs)
  File "/home/m0nd2y/.local/lib/python3.8/site-packages/flask/views.py", line 109, in view
    return current_app.ensure_sync(self.dispatch_request)(**kwargs)
  File "/home/m0nd2y/.local/lib/python3.8/site-packages/flask_restx/resource.py", line 46, in dispatch_request
    resp = meth(*args, **kwargs)
  File "/home/m0nd2y/SearchVuln/app.py", line 56, in post
    print(api.paylode)
  File "/home/m0nd2y/.local/lib/python3.8/site-packages/flask_restx/api.py", line 285, in __getattr__
    raise AttributeError("Api does not have {0} attribute".format(name))
AttributeError: Api does not have paylode attribute
127.0.0.1 - - [14/Jun/2023 05:49:36] "POST /SearchVuln/ HTTP/1.1" 200 -
127.0.0.1 - - [14/Jun/2023 05:49:36] "POST /SearchVuln/ HTTP/1.1" 200 -
127.0.0.1 - - [14/Jun/2023 05:49:37] "POST /SearchVuln/ HTTP/1.1" 200 -
127.0.0.1 - - [14/Jun/2023 05:49:39] "POST /SearchVuln/ HTTP/1.1" 200 -
127.0.0.1 - - [14/Jun/2023 05:50:26] "POST /SearchDep/ HTTP/1.1" 500 -
Traceback (most recent call last):
  File "/home/m0nd2y/.local/lib/python3.8/site-packages/flask_restx/api.py", line 283, in __getattr__
    return getattr(self.default_namespace, name)
AttributeError: 'Namespace' object has no attribute 'paylode'

During handling of the above exception, another exception occurred:

Traceback (most recent call last):
  File "/home/m0nd2y/.local/lib/python3.8/site-packages/flask/app.py", line 2213, in __call__
    return self.wsgi_app(environ, start_response)
  File "/home/m0nd2y/.local/lib/python3.8/site-packages/flask/app.py", line 2193, in wsgi_app
    response = self.handle_exception(e)
  File "/home/m0nd2y/.local/lib/python3.8/site-packages/flask_restx/api.py", line 673, in error_router
    return original_handler(f)
  File "/home/m0nd2y/.local/lib/python3.8/site-packages/flask_restx/api.py", line 671, in error_router
    return self.handle_error(e)
  File "/home/m0nd2y/.local/lib/python3.8/site-packages/flask/app.py", line 2190, in wsgi_app
    response = self.full_dispatch_request()
  File "/home/m0nd2y/.local/lib/python3.8/site-packages/flask/app.py", line 1486, in full_dispatch_request
    rv = self.handle_user_exception(e)
  File "/home/m0nd2y/.local/lib/python3.8/site-packages/flask_restx/api.py", line 673, in error_router
    return original_handler(f)
  File "/home/m0nd2y/.local/lib/python3.8/site-packages/flask_restx/api.py", line 671, in error_router
    return self.handle_error(e)
  File "/home/m0nd2y/.local/lib/python3.8/site-packages/flask/app.py", line 1484, in full_dispatch_request
    rv = self.dispatch_request()
  File "/home/m0nd2y/.local/lib/python3.8/site-packages/flask/app.py", line 1469, in dispatch_request
    return self.ensure_sync(self.view_functions[rule.endpoint])(**view_args)
  File "/home/m0nd2y/.local/lib/python3.8/site-packages/flask_restx/api.py", line 404, in wrapper
    resp = resource(*args, **kwargs)
  File "/home/m0nd2y/.local/lib/python3.8/site-packages/flask/views.py", line 109, in view
    return current_app.ensure_sync(self.dispatch_request)(**kwargs)
  File "/home/m0nd2y/.local/lib/python3.8/site-packages/flask_restx/resource.py", line 46, in dispatch_request
    resp = meth(*args, **kwargs)
  File "/home/m0nd2y/SearchVuln/app.py", line 56, in post
    print(api.paylode)
  File "/home/m0nd2y/.local/lib/python3.8/site-packages/flask_restx/api.py", line 285, in __getattr__
    raise AttributeError("Api does not have {0} attribute".format(name))
AttributeError: Api does not have paylode attribute
127.0.0.1 - - [14/Jun/2023 05:50:26] "POST /SearchVuln/ HTTP/1.1" 200 -
127.0.0.1 - - [14/Jun/2023 05:50:26] "POST /SearchVuln/ HTTP/1.1" 200 -
127.0.0.1 - - [14/Jun/2023 05:50:26] "POST /SearchVuln/ HTTP/1.1" 200 -
127.0.0.1 - - [14/Jun/2023 05:50:26] "POST /SearchVuln/ HTTP/1.1" 200 -
127.0.0.1 - - [14/Jun/2023 05:51:01] "POST /SearchDep/ HTTP/1.1" 500 -
Traceback (most recent call last):
  File "/home/m0nd2y/.local/lib/python3.8/site-packages/flask_restx/api.py", line 283, in __getattr__
    return getattr(self.default_namespace, name)
AttributeError: 'Namespace' object has no attribute 'paylode'

During handling of the above exception, another exception occurred:

Traceback (most recent call last):
  File "/home/m0nd2y/.local/lib/python3.8/site-packages/flask/app.py", line 2213, in __call__
    return self.wsgi_app(environ, start_response)
  File "/home/m0nd2y/.local/lib/python3.8/site-packages/flask/app.py", line 2193, in wsgi_app
    response = self.handle_exception(e)
  File "/home/m0nd2y/.local/lib/python3.8/site-packages/flask_restx/api.py", line 673, in error_router
    return original_handler(f)
  File "/home/m0nd2y/.local/lib/python3.8/site-packages/flask_restx/api.py", line 671, in error_router
    return self.handle_error(e)
  File "/home/m0nd2y/.local/lib/python3.8/site-packages/flask/app.py", line 2190, in wsgi_app
    response = self.full_dispatch_request()
  File "/home/m0nd2y/.local/lib/python3.8/site-packages/flask/app.py", line 1486, in full_dispatch_request
    rv = self.handle_user_exception(e)
  File "/home/m0nd2y/.local/lib/python3.8/site-packages/flask_restx/api.py", line 673, in error_router
    return original_handler(f)
  File "/home/m0nd2y/.local/lib/python3.8/site-packages/flask_restx/api.py", line 671, in error_router
    return self.handle_error(e)
  File "/home/m0nd2y/.local/lib/python3.8/site-packages/flask/app.py", line 1484, in full_dispatch_request
    rv = self.dispatch_request()
  File "/home/m0nd2y/.local/lib/python3.8/site-packages/flask/app.py", line 1469, in dispatch_request
    return self.ensure_sync(self.view_functions[rule.endpoint])(**view_args)
  File "/home/m0nd2y/.local/lib/python3.8/site-packages/flask_restx/api.py", line 404, in wrapper
    resp = resource(*args, **kwargs)
  File "/home/m0nd2y/.local/lib/python3.8/site-packages/flask/views.py", line 109, in view
    return current_app.ensure_sync(self.dispatch_request)(**kwargs)
  File "/home/m0nd2y/.local/lib/python3.8/site-packages/flask_restx/resource.py", line 46, in dispatch_request
    resp = meth(*args, **kwargs)
  File "/home/m0nd2y/SearchVuln/app.py", line 56, in post
    print(api.paylode)
  File "/home/m0nd2y/.local/lib/python3.8/site-packages/flask_restx/api.py", line 285, in __getattr__
    raise AttributeError("Api does not have {0} attribute".format(name))
AttributeError: Api does not have paylode attribute
127.0.0.1 - - [14/Jun/2023 05:51:01] "POST /SearchVuln/ HTTP/1.1" 200 -
127.0.0.1 - - [14/Jun/2023 05:51:01] "POST /SearchVuln/ HTTP/1.1" 200 -
127.0.0.1 - - [14/Jun/2023 05:51:01] "POST /SearchVuln/ HTTP/1.1" 200 -
127.0.0.1 - - [14/Jun/2023 05:51:01] "POST /SearchVuln/ HTTP/1.1" 200 -
127.0.0.1 - - [14/Jun/2023 05:51:02] "POST /SearchDep/ HTTP/1.1" 500 -
Traceback (most recent call last):
  File "/home/m0nd2y/.local/lib/python3.8/site-packages/flask_restx/api.py", line 283, in __getattr__
    return getattr(self.default_namespace, name)
AttributeError: 'Namespace' object has no attribute 'paylode'

During handling of the above exception, another exception occurred:

Traceback (most recent call last):
  File "/home/m0nd2y/.local/lib/python3.8/site-packages/flask/app.py", line 2213, in __call__
    return self.wsgi_app(environ, start_response)
  File "/home/m0nd2y/.local/lib/python3.8/site-packages/flask/app.py", line 2193, in wsgi_app
    response = self.handle_exception(e)
  File "/home/m0nd2y/.local/lib/python3.8/site-packages/flask_restx/api.py", line 673, in error_router
    return original_handler(f)
  File "/home/m0nd2y/.local/lib/python3.8/site-packages/flask_restx/api.py", line 671, in error_router
    return self.handle_error(e)
  File "/home/m0nd2y/.local/lib/python3.8/site-packages/flask/app.py", line 2190, in wsgi_app
    response = self.full_dispatch_request()
  File "/home/m0nd2y/.local/lib/python3.8/site-packages/flask/app.py", line 1486, in full_dispatch_request
    rv = self.handle_user_exception(e)
  File "/home/m0nd2y/.local/lib/python3.8/site-packages/flask_restx/api.py", line 673, in error_router
    return original_handler(f)
  File "/home/m0nd2y/.local/lib/python3.8/site-packages/flask_restx/api.py", line 671, in error_router
    return self.handle_error(e)
  File "/home/m0nd2y/.local/lib/python3.8/site-packages/flask/app.py", line 1484, in full_dispatch_request
    rv = self.dispatch_request()
  File "/home/m0nd2y/.local/lib/python3.8/site-packages/flask/app.py", line 1469, in dispatch_request
    return self.ensure_sync(self.view_functions[rule.endpoint])(**view_args)
  File "/home/m0nd2y/.local/lib/python3.8/site-packages/flask_restx/api.py", line 404, in wrapper
    resp = resource(*args, **kwargs)
  File "/home/m0nd2y/.local/lib/python3.8/site-packages/flask/views.py", line 109, in view
    return current_app.ensure_sync(self.dispatch_request)(**kwargs)
  File "/home/m0nd2y/.local/lib/python3.8/site-packages/flask_restx/resource.py", line 46, in dispatch_request
    resp = meth(*args, **kwargs)
  File "/home/m0nd2y/SearchVuln/app.py", line 56, in post
    print(api.paylode)
  File "/home/m0nd2y/.local/lib/python3.8/site-packages/flask_restx/api.py", line 285, in __getattr__
    raise AttributeError("Api does not have {0} attribute".format(name))
AttributeError: Api does not have paylode attribute
127.0.0.1 - - [14/Jun/2023 05:51:02] "POST /SearchVuln/ HTTP/1.1" 200 -
127.0.0.1 - - [14/Jun/2023 05:51:03] "POST /SearchVuln/ HTTP/1.1" 200 -
127.0.0.1 - - [14/Jun/2023 05:51:03] "POST /SearchVuln/ HTTP/1.1" 200 -
127.0.0.1 - - [14/Jun/2023 05:51:03] "POST /SearchVuln/ HTTP/1.1" 200 -
127.0.0.1 - - [14/Jun/2023 05:51:20] "POST /SearchDep/ HTTP/1.1" 500 -
Traceback (most recent call last):
  File "/home/m0nd2y/.local/lib/python3.8/site-packages/flask_restx/api.py", line 283, in __getattr__
    return getattr(self.default_namespace, name)
AttributeError: 'Namespace' object has no attribute 'paylode'

During handling of the above exception, another exception occurred:

Traceback (most recent call last):
  File "/home/m0nd2y/.local/lib/python3.8/site-packages/flask/app.py", line 2213, in __call__
    return self.wsgi_app(environ, start_response)
  File "/home/m0nd2y/.local/lib/python3.8/site-packages/flask/app.py", line 2193, in wsgi_app
    response = self.handle_exception(e)
  File "/home/m0nd2y/.local/lib/python3.8/site-packages/flask_restx/api.py", line 673, in error_router
    return original_handler(f)
  File "/home/m0nd2y/.local/lib/python3.8/site-packages/flask_restx/api.py", line 671, in error_router
    return self.handle_error(e)
  File "/home/m0nd2y/.local/lib/python3.8/site-packages/flask/app.py", line 2190, in wsgi_app
    response = self.full_dispatch_request()
  File "/home/m0nd2y/.local/lib/python3.8/site-packages/flask/app.py", line 1486, in full_dispatch_request
    rv = self.handle_user_exception(e)
  File "/home/m0nd2y/.local/lib/python3.8/site-packages/flask_restx/api.py", line 673, in error_router
    return original_handler(f)
  File "/home/m0nd2y/.local/lib/python3.8/site-packages/flask_restx/api.py", line 671, in error_router
    return self.handle_error(e)
  File "/home/m0nd2y/.local/lib/python3.8/site-packages/flask/app.py", line 1484, in full_dispatch_request
    rv = self.dispatch_request()
  File "/home/m0nd2y/.local/lib/python3.8/site-packages/flask/app.py", line 1469, in dispatch_request
    return self.ensure_sync(self.view_functions[rule.endpoint])(**view_args)
  File "/home/m0nd2y/.local/lib/python3.8/site-packages/flask_restx/api.py", line 404, in wrapper
    resp = resource(*args, **kwargs)
  File "/home/m0nd2y/.local/lib/python3.8/site-packages/flask/views.py", line 109, in view
    return current_app.ensure_sync(self.dispatch_request)(**kwargs)
  File "/home/m0nd2y/.local/lib/python3.8/site-packages/flask_restx/resource.py", line 46, in dispatch_request
    resp = meth(*args, **kwargs)
  File "/home/m0nd2y/SearchVuln/app.py", line 56, in post
    print(api.paylode)
  File "/home/m0nd2y/.local/lib/python3.8/site-packages/flask_restx/api.py", line 285, in __getattr__
    raise AttributeError("Api does not have {0} attribute".format(name))
AttributeError: Api does not have paylode attribute
127.0.0.1 - - [14/Jun/2023 05:51:20] "POST /SearchVuln/ HTTP/1.1" 200 -
127.0.0.1 - - [14/Jun/2023 05:51:20] "POST /SearchVuln/ HTTP/1.1" 200 -
127.0.0.1 - - [14/Jun/2023 05:51:20] "POST /SearchVuln/ HTTP/1.1" 200 -
127.0.0.1 - - [14/Jun/2023 05:51:20] "POST /SearchVuln/ HTTP/1.1" 200 -
127.0.0.1 - - [14/Jun/2023 05:51:26] "POST /SearchDep/ HTTP/1.1" 500 -
Traceback (most recent call last):
  File "/home/m0nd2y/.local/lib/python3.8/site-packages/flask_restx/api.py", line 283, in __getattr__
    return getattr(self.default_namespace, name)
AttributeError: 'Namespace' object has no attribute 'paylode'

During handling of the above exception, another exception occurred:

Traceback (most recent call last):
  File "/home/m0nd2y/.local/lib/python3.8/site-packages/flask/app.py", line 2213, in __call__
    return self.wsgi_app(environ, start_response)
  File "/home/m0nd2y/.local/lib/python3.8/site-packages/flask/app.py", line 2193, in wsgi_app
    response = self.handle_exception(e)
  File "/home/m0nd2y/.local/lib/python3.8/site-packages/flask_restx/api.py", line 673, in error_router
    return original_handler(f)
  File "/home/m0nd2y/.local/lib/python3.8/site-packages/flask_restx/api.py", line 671, in error_router
    return self.handle_error(e)
  File "/home/m0nd2y/.local/lib/python3.8/site-packages/flask/app.py", line 2190, in wsgi_app
    response = self.full_dispatch_request()
  File "/home/m0nd2y/.local/lib/python3.8/site-packages/flask/app.py", line 1486, in full_dispatch_request
    rv = self.handle_user_exception(e)
  File "/home/m0nd2y/.local/lib/python3.8/site-packages/flask_restx/api.py", line 673, in error_router
    return original_handler(f)
  File "/home/m0nd2y/.local/lib/python3.8/site-packages/flask_restx/api.py", line 671, in error_router
    return self.handle_error(e)
  File "/home/m0nd2y/.local/lib/python3.8/site-packages/flask/app.py", line 1484, in full_dispatch_request
    rv = self.dispatch_request()
  File "/home/m0nd2y/.local/lib/python3.8/site-packages/flask/app.py", line 1469, in dispatch_request
    return self.ensure_sync(self.view_functions[rule.endpoint])(**view_args)
  File "/home/m0nd2y/.local/lib/python3.8/site-packages/flask_restx/api.py", line 404, in wrapper
    resp = resource(*args, **kwargs)
  File "/home/m0nd2y/.local/lib/python3.8/site-packages/flask/views.py", line 109, in view
    return current_app.ensure_sync(self.dispatch_request)(**kwargs)
  File "/home/m0nd2y/.local/lib/python3.8/site-packages/flask_restx/resource.py", line 46, in dispatch_request
    resp = meth(*args, **kwargs)
  File "/home/m0nd2y/SearchVuln/app.py", line 56, in post
    print(api.paylode)
  File "/home/m0nd2y/.local/lib/python3.8/site-packages/flask_restx/api.py", line 285, in __getattr__
    raise AttributeError("Api does not have {0} attribute".format(name))
AttributeError: Api does not have paylode attribute
127.0.0.1 - - [14/Jun/2023 05:51:27] "POST /SearchVuln/ HTTP/1.1" 200 -
127.0.0.1 - - [14/Jun/2023 05:51:27] "POST /SearchVuln/ HTTP/1.1" 200 -
127.0.0.1 - - [14/Jun/2023 05:51:27] "POST /SearchVuln/ HTTP/1.1" 200 -
127.0.0.1 - - [14/Jun/2023 05:51:27] "POST /SearchVuln/ HTTP/1.1" 200 -
127.0.0.1 - - [14/Jun/2023 05:52:35] "POST /SearchDep/ HTTP/1.1" 500 -
Traceback (most recent call last):
  File "/home/m0nd2y/.local/lib/python3.8/site-packages/flask_restx/api.py", line 283, in __getattr__
    return getattr(self.default_namespace, name)
AttributeError: 'Namespace' object has no attribute 'paylode'

During handling of the above exception, another exception occurred:

Traceback (most recent call last):
  File "/home/m0nd2y/.local/lib/python3.8/site-packages/flask/app.py", line 2213, in __call__
    return self.wsgi_app(environ, start_response)
  File "/home/m0nd2y/.local/lib/python3.8/site-packages/flask/app.py", line 2193, in wsgi_app
    response = self.handle_exception(e)
  File "/home/m0nd2y/.local/lib/python3.8/site-packages/flask_restx/api.py", line 673, in error_router
    return original_handler(f)
  File "/home/m0nd2y/.local/lib/python3.8/site-packages/flask_restx/api.py", line 671, in error_router
    return self.handle_error(e)
  File "/home/m0nd2y/.local/lib/python3.8/site-packages/flask/app.py", line 2190, in wsgi_app
    response = self.full_dispatch_request()
  File "/home/m0nd2y/.local/lib/python3.8/site-packages/flask/app.py", line 1486, in full_dispatch_request
    rv = self.handle_user_exception(e)
  File "/home/m0nd2y/.local/lib/python3.8/site-packages/flask_restx/api.py", line 673, in error_router
    return original_handler(f)
  File "/home/m0nd2y/.local/lib/python3.8/site-packages/flask_restx/api.py", line 671, in error_router
    return self.handle_error(e)
  File "/home/m0nd2y/.local/lib/python3.8/site-packages/flask/app.py", line 1484, in full_dispatch_request
    rv = self.dispatch_request()
  File "/home/m0nd2y/.local/lib/python3.8/site-packages/flask/app.py", line 1469, in dispatch_request
    return self.ensure_sync(self.view_functions[rule.endpoint])(**view_args)
  File "/home/m0nd2y/.local/lib/python3.8/site-packages/flask_restx/api.py", line 404, in wrapper
    resp = resource(*args, **kwargs)
  File "/home/m0nd2y/.local/lib/python3.8/site-packages/flask/views.py", line 109, in view
    return current_app.ensure_sync(self.dispatch_request)(**kwargs)
  File "/home/m0nd2y/.local/lib/python3.8/site-packages/flask_restx/resource.py", line 46, in dispatch_request
    resp = meth(*args, **kwargs)
  File "/home/m0nd2y/SearchVuln/app.py", line 56, in post
    print(api.paylode)
  File "/home/m0nd2y/.local/lib/python3.8/site-packages/flask_restx/api.py", line 285, in __getattr__
    raise AttributeError("Api does not have {0} attribute".format(name))
AttributeError: Api does not have paylode attribute
127.0.0.1 - - [14/Jun/2023 05:52:35] "POST /SearchVuln/ HTTP/1.1" 200 -
127.0.0.1 - - [14/Jun/2023 05:52:35] "POST /SearchVuln/ HTTP/1.1" 200 -
127.0.0.1 - - [14/Jun/2023 05:52:35] "POST /SearchVuln/ HTTP/1.1" 200 -
127.0.0.1 - - [14/Jun/2023 05:52:35] "POST /SearchVuln/ HTTP/1.1" 200 -
127.0.0.1 - - [14/Jun/2023 05:53:01] "POST /SearchDep/ HTTP/1.1" 500 -
Traceback (most recent call last):
  File "/home/m0nd2y/.local/lib/python3.8/site-packages/flask_restx/api.py", line 283, in __getattr__
    return getattr(self.default_namespace, name)
AttributeError: 'Namespace' object has no attribute 'paylode'

During handling of the above exception, another exception occurred:

Traceback (most recent call last):
  File "/home/m0nd2y/.local/lib/python3.8/site-packages/flask/app.py", line 2213, in __call__
    return self.wsgi_app(environ, start_response)
  File "/home/m0nd2y/.local/lib/python3.8/site-packages/flask/app.py", line 2193, in wsgi_app
    response = self.handle_exception(e)
  File "/home/m0nd2y/.local/lib/python3.8/site-packages/flask_restx/api.py", line 673, in error_router
    return original_handler(f)
  File "/home/m0nd2y/.local/lib/python3.8/site-packages/flask_restx/api.py", line 671, in error_router
    return self.handle_error(e)
  File "/home/m0nd2y/.local/lib/python3.8/site-packages/flask/app.py", line 2190, in wsgi_app
    response = self.full_dispatch_request()
  File "/home/m0nd2y/.local/lib/python3.8/site-packages/flask/app.py", line 1486, in full_dispatch_request
    rv = self.handle_user_exception(e)
  File "/home/m0nd2y/.local/lib/python3.8/site-packages/flask_restx/api.py", line 673, in error_router
    return original_handler(f)
  File "/home/m0nd2y/.local/lib/python3.8/site-packages/flask_restx/api.py", line 671, in error_router
    return self.handle_error(e)
  File "/home/m0nd2y/.local/lib/python3.8/site-packages/flask/app.py", line 1484, in full_dispatch_request
    rv = self.dispatch_request()
  File "/home/m0nd2y/.local/lib/python3.8/site-packages/flask/app.py", line 1469, in dispatch_request
    return self.ensure_sync(self.view_functions[rule.endpoint])(**view_args)
  File "/home/m0nd2y/.local/lib/python3.8/site-packages/flask_restx/api.py", line 404, in wrapper
    resp = resource(*args, **kwargs)
  File "/home/m0nd2y/.local/lib/python3.8/site-packages/flask/views.py", line 109, in view
    return current_app.ensure_sync(self.dispatch_request)(**kwargs)
  File "/home/m0nd2y/.local/lib/python3.8/site-packages/flask_restx/resource.py", line 46, in dispatch_request
    resp = meth(*args, **kwargs)
  File "/home/m0nd2y/SearchVuln/app.py", line 56, in post
    print(api.paylode)
  File "/home/m0nd2y/.local/lib/python3.8/site-packages/flask_restx/api.py", line 285, in __getattr__
    raise AttributeError("Api does not have {0} attribute".format(name))
AttributeError: Api does not have paylode attribute
127.0.0.1 - - [14/Jun/2023 05:53:02] "POST /SearchVuln/ HTTP/1.1" 200 -
127.0.0.1 - - [14/Jun/2023 05:53:02] "POST /SearchVuln/ HTTP/1.1" 200 -
127.0.0.1 - - [14/Jun/2023 05:53:02] "POST /SearchVuln/ HTTP/1.1" 200 -
127.0.0.1 - - [14/Jun/2023 05:53:02] "POST /SearchVuln/ HTTP/1.1" 200 -
127.0.0.1 - - [14/Jun/2023 05:53:17] "POST /SearchDep/ HTTP/1.1" 500 -
Traceback (most recent call last):
  File "/home/m0nd2y/.local/lib/python3.8/site-packages/flask_restx/api.py", line 283, in __getattr__
    return getattr(self.default_namespace, name)
AttributeError: 'Namespace' object has no attribute 'paylode'

During handling of the above exception, another exception occurred:

Traceback (most recent call last):
  File "/home/m0nd2y/.local/lib/python3.8/site-packages/flask/app.py", line 2213, in __call__
    return self.wsgi_app(environ, start_response)
  File "/home/m0nd2y/.local/lib/python3.8/site-packages/flask/app.py", line 2193, in wsgi_app
    response = self.handle_exception(e)
  File "/home/m0nd2y/.local/lib/python3.8/site-packages/flask_restx/api.py", line 673, in error_router
    return original_handler(f)
  File "/home/m0nd2y/.local/lib/python3.8/site-packages/flask_restx/api.py", line 671, in error_router
    return self.handle_error(e)
  File "/home/m0nd2y/.local/lib/python3.8/site-packages/flask/app.py", line 2190, in wsgi_app
    response = self.full_dispatch_request()
  File "/home/m0nd2y/.local/lib/python3.8/site-packages/flask/app.py", line 1486, in full_dispatch_request
    rv = self.handle_user_exception(e)
  File "/home/m0nd2y/.local/lib/python3.8/site-packages/flask_restx/api.py", line 673, in error_router
    return original_handler(f)
  File "/home/m0nd2y/.local/lib/python3.8/site-packages/flask_restx/api.py", line 671, in error_router
    return self.handle_error(e)
  File "/home/m0nd2y/.local/lib/python3.8/site-packages/flask/app.py", line 1484, in full_dispatch_request
    rv = self.dispatch_request()
  File "/home/m0nd2y/.local/lib/python3.8/site-packages/flask/app.py", line 1469, in dispatch_request
    return self.ensure_sync(self.view_functions[rule.endpoint])(**view_args)
  File "/home/m0nd2y/.local/lib/python3.8/site-packages/flask_restx/api.py", line 404, in wrapper
    resp = resource(*args, **kwargs)
  File "/home/m0nd2y/.local/lib/python3.8/site-packages/flask/views.py", line 109, in view
    return current_app.ensure_sync(self.dispatch_request)(**kwargs)
  File "/home/m0nd2y/.local/lib/python3.8/site-packages/flask_restx/resource.py", line 46, in dispatch_request
    resp = meth(*args, **kwargs)
  File "/home/m0nd2y/SearchVuln/app.py", line 56, in post
    print(api.paylode)
  File "/home/m0nd2y/.local/lib/python3.8/site-packages/flask_restx/api.py", line 285, in __getattr__
    raise AttributeError("Api does not have {0} attribute".format(name))
AttributeError: Api does not have paylode attribute
127.0.0.1 - - [14/Jun/2023 05:53:17] "POST /SearchVuln/ HTTP/1.1" 200 -
127.0.0.1 - - [14/Jun/2023 05:53:17] "POST /SearchVuln/ HTTP/1.1" 200 -
127.0.0.1 - - [14/Jun/2023 05:53:17] "POST /SearchVuln/ HTTP/1.1" 200 -
127.0.0.1 - - [14/Jun/2023 05:53:17] "POST /SearchVuln/ HTTP/1.1" 200 -
127.0.0.1 - - [14/Jun/2023 05:53:26] "POST /SearchDep/ HTTP/1.1" 500 -
Traceback (most recent call last):
  File "/home/m0nd2y/.local/lib/python3.8/site-packages/flask_restx/api.py", line 283, in __getattr__
    return getattr(self.default_namespace, name)
AttributeError: 'Namespace' object has no attribute 'paylode'

During handling of the above exception, another exception occurred:

Traceback (most recent call last):
  File "/home/m0nd2y/.local/lib/python3.8/site-packages/flask/app.py", line 2213, in __call__
    return self.wsgi_app(environ, start_response)
  File "/home/m0nd2y/.local/lib/python3.8/site-packages/flask/app.py", line 2193, in wsgi_app
    response = self.handle_exception(e)
  File "/home/m0nd2y/.local/lib/python3.8/site-packages/flask_restx/api.py", line 673, in error_router
    return original_handler(f)
  File "/home/m0nd2y/.local/lib/python3.8/site-packages/flask_restx/api.py", line 671, in error_router
    return self.handle_error(e)
  File "/home/m0nd2y/.local/lib/python3.8/site-packages/flask/app.py", line 2190, in wsgi_app
    response = self.full_dispatch_request()
  File "/home/m0nd2y/.local/lib/python3.8/site-packages/flask/app.py", line 1486, in full_dispatch_request
    rv = self.handle_user_exception(e)
  File "/home/m0nd2y/.local/lib/python3.8/site-packages/flask_restx/api.py", line 673, in error_router
    return original_handler(f)
  File "/home/m0nd2y/.local/lib/python3.8/site-packages/flask_restx/api.py", line 671, in error_router
    return self.handle_error(e)
  File "/home/m0nd2y/.local/lib/python3.8/site-packages/flask/app.py", line 1484, in full_dispatch_request
    rv = self.dispatch_request()
  File "/home/m0nd2y/.local/lib/python3.8/site-packages/flask/app.py", line 1469, in dispatch_request
    return self.ensure_sync(self.view_functions[rule.endpoint])(**view_args)
  File "/home/m0nd2y/.local/lib/python3.8/site-packages/flask_restx/api.py", line 404, in wrapper
    resp = resource(*args, **kwargs)
  File "/home/m0nd2y/.local/lib/python3.8/site-packages/flask/views.py", line 109, in view
    return current_app.ensure_sync(self.dispatch_request)(**kwargs)
  File "/home/m0nd2y/.local/lib/python3.8/site-packages/flask_restx/resource.py", line 46, in dispatch_request
    resp = meth(*args, **kwargs)
  File "/home/m0nd2y/SearchVuln/app.py", line 56, in post
    print(api.paylode)
  File "/home/m0nd2y/.local/lib/python3.8/site-packages/flask_restx/api.py", line 285, in __getattr__
    raise AttributeError("Api does not have {0} attribute".format(name))
AttributeError: Api does not have paylode attribute
127.0.0.1 - - [14/Jun/2023 05:53:27] "POST /SearchVuln/ HTTP/1.1" 200 -
127.0.0.1 - - [14/Jun/2023 05:53:27] "POST /SearchVuln/ HTTP/1.1" 200 -
127.0.0.1 - - [14/Jun/2023 05:53:27] "POST /SearchVuln/ HTTP/1.1" 200 -
127.0.0.1 - - [14/Jun/2023 05:53:27] "POST /SearchVuln/ HTTP/1.1" 200 -
127.0.0.1 - - [14/Jun/2023 05:53:37] "POST /SearchDep/ HTTP/1.1" 500 -
Traceback (most recent call last):
  File "/home/m0nd2y/.local/lib/python3.8/site-packages/flask_restx/api.py", line 283, in __getattr__
    return getattr(self.default_namespace, name)
AttributeError: 'Namespace' object has no attribute 'paylode'

During handling of the above exception, another exception occurred:

Traceback (most recent call last):
  File "/home/m0nd2y/.local/lib/python3.8/site-packages/flask/app.py", line 2213, in __call__
    return self.wsgi_app(environ, start_response)
  File "/home/m0nd2y/.local/lib/python3.8/site-packages/flask/app.py", line 2193, in wsgi_app
    response = self.handle_exception(e)
  File "/home/m0nd2y/.local/lib/python3.8/site-packages/flask_restx/api.py", line 673, in error_router
    return original_handler(f)
  File "/home/m0nd2y/.local/lib/python3.8/site-packages/flask_restx/api.py", line 671, in error_router
    return self.handle_error(e)
  File "/home/m0nd2y/.local/lib/python3.8/site-packages/flask/app.py", line 2190, in wsgi_app
    response = self.full_dispatch_request()
  File "/home/m0nd2y/.local/lib/python3.8/site-packages/flask/app.py", line 1486, in full_dispatch_request
    rv = self.handle_user_exception(e)
  File "/home/m0nd2y/.local/lib/python3.8/site-packages/flask_restx/api.py", line 673, in error_router
    return original_handler(f)
  File "/home/m0nd2y/.local/lib/python3.8/site-packages/flask_restx/api.py", line 671, in error_router
    return self.handle_error(e)
  File "/home/m0nd2y/.local/lib/python3.8/site-packages/flask/app.py", line 1484, in full_dispatch_request
    rv = self.dispatch_request()
  File "/home/m0nd2y/.local/lib/python3.8/site-packages/flask/app.py", line 1469, in dispatch_request
    return self.ensure_sync(self.view_functions[rule.endpoint])(**view_args)
  File "/home/m0nd2y/.local/lib/python3.8/site-packages/flask_restx/api.py", line 404, in wrapper
    resp = resource(*args, **kwargs)
  File "/home/m0nd2y/.local/lib/python3.8/site-packages/flask/views.py", line 109, in view
    return current_app.ensure_sync(self.dispatch_request)(**kwargs)
  File "/home/m0nd2y/.local/lib/python3.8/site-packages/flask_restx/resource.py", line 46, in dispatch_request
    resp = meth(*args, **kwargs)
  File "/home/m0nd2y/SearchVuln/app.py", line 56, in post
    print(api.paylode)
  File "/home/m0nd2y/.local/lib/python3.8/site-packages/flask_restx/api.py", line 285, in __getattr__
    raise AttributeError("Api does not have {0} attribute".format(name))
AttributeError: Api does not have paylode attribute
127.0.0.1 - - [14/Jun/2023 05:53:37] "POST /SearchVuln/ HTTP/1.1" 200 -
127.0.0.1 - - [14/Jun/2023 05:53:37] "POST /SearchVuln/ HTTP/1.1" 200 -
127.0.0.1 - - [14/Jun/2023 05:53:37] "POST /SearchVuln/ HTTP/1.1" 200 -
127.0.0.1 - - [14/Jun/2023 05:53:38] "POST /SearchVuln/ HTTP/1.1" 200 -
127.0.0.1 - - [14/Jun/2023 05:53:57] "POST /SearchDep/ HTTP/1.1" 500 -
Traceback (most recent call last):
  File "/home/m0nd2y/.local/lib/python3.8/site-packages/flask_restx/api.py", line 283, in __getattr__
    return getattr(self.default_namespace, name)
AttributeError: 'Namespace' object has no attribute 'paylode'

During handling of the above exception, another exception occurred:

Traceback (most recent call last):
  File "/home/m0nd2y/.local/lib/python3.8/site-packages/flask/app.py", line 2213, in __call__
    return self.wsgi_app(environ, start_response)
  File "/home/m0nd2y/.local/lib/python3.8/site-packages/flask/app.py", line 2193, in wsgi_app
    response = self.handle_exception(e)
  File "/home/m0nd2y/.local/lib/python3.8/site-packages/flask_restx/api.py", line 673, in error_router
    return original_handler(f)
  File "/home/m0nd2y/.local/lib/python3.8/site-packages/flask_restx/api.py", line 671, in error_router
    return self.handle_error(e)
  File "/home/m0nd2y/.local/lib/python3.8/site-packages/flask/app.py", line 2190, in wsgi_app
    response = self.full_dispatch_request()
  File "/home/m0nd2y/.local/lib/python3.8/site-packages/flask/app.py", line 1486, in full_dispatch_request
    rv = self.handle_user_exception(e)
  File "/home/m0nd2y/.local/lib/python3.8/site-packages/flask_restx/api.py", line 673, in error_router
    return original_handler(f)
  File "/home/m0nd2y/.local/lib/python3.8/site-packages/flask_restx/api.py", line 671, in error_router
    return self.handle_error(e)
  File "/home/m0nd2y/.local/lib/python3.8/site-packages/flask/app.py", line 1484, in full_dispatch_request
    rv = self.dispatch_request()
  File "/home/m0nd2y/.local/lib/python3.8/site-packages/flask/app.py", line 1469, in dispatch_request
    return self.ensure_sync(self.view_functions[rule.endpoint])(**view_args)
  File "/home/m0nd2y/.local/lib/python3.8/site-packages/flask_restx/api.py", line 404, in wrapper
    resp = resource(*args, **kwargs)
  File "/home/m0nd2y/.local/lib/python3.8/site-packages/flask/views.py", line 109, in view
    return current_app.ensure_sync(self.dispatch_request)(**kwargs)
  File "/home/m0nd2y/.local/lib/python3.8/site-packages/flask_restx/resource.py", line 46, in dispatch_request
    resp = meth(*args, **kwargs)
  File "/home/m0nd2y/SearchVuln/app.py", line 56, in post
    print(api.paylode)
  File "/home/m0nd2y/.local/lib/python3.8/site-packages/flask_restx/api.py", line 285, in __getattr__
    raise AttributeError("Api does not have {0} attribute".format(name))
AttributeError: Api does not have paylode attribute
127.0.0.1 - - [14/Jun/2023 05:53:57] "POST /SearchVuln/ HTTP/1.1" 200 -
127.0.0.1 - - [14/Jun/2023 05:53:57] "POST /SearchVuln/ HTTP/1.1" 200 -
127.0.0.1 - - [14/Jun/2023 05:53:57] "POST /SearchVuln/ HTTP/1.1" 200 -
127.0.0.1 - - [14/Jun/2023 05:53:57] "POST /SearchVuln/ HTTP/1.1" 200 -
127.0.0.1 - - [14/Jun/2023 05:54:00] "POST /SearchDep/ HTTP/1.1" 500 -
Traceback (most recent call last):
  File "/home/m0nd2y/.local/lib/python3.8/site-packages/flask_restx/api.py", line 283, in __getattr__
    return getattr(self.default_namespace, name)
AttributeError: 'Namespace' object has no attribute 'paylode'

During handling of the above exception, another exception occurred:

Traceback (most recent call last):
  File "/home/m0nd2y/.local/lib/python3.8/site-packages/flask/app.py", line 2213, in __call__
    return self.wsgi_app(environ, start_response)
  File "/home/m0nd2y/.local/lib/python3.8/site-packages/flask/app.py", line 2193, in wsgi_app
    response = self.handle_exception(e)
  File "/home/m0nd2y/.local/lib/python3.8/site-packages/flask_restx/api.py", line 673, in error_router
    return original_handler(f)
  File "/home/m0nd2y/.local/lib/python3.8/site-packages/flask_restx/api.py", line 671, in error_router
    return self.handle_error(e)
  File "/home/m0nd2y/.local/lib/python3.8/site-packages/flask/app.py", line 2190, in wsgi_app
    response = self.full_dispatch_request()
  File "/home/m0nd2y/.local/lib/python3.8/site-packages/flask/app.py", line 1486, in full_dispatch_request
    rv = self.handle_user_exception(e)
  File "/home/m0nd2y/.local/lib/python3.8/site-packages/flask_restx/api.py", line 673, in error_router
    return original_handler(f)
  File "/home/m0nd2y/.local/lib/python3.8/site-packages/flask_restx/api.py", line 671, in error_router
    return self.handle_error(e)
  File "/home/m0nd2y/.local/lib/python3.8/site-packages/flask/app.py", line 1484, in full_dispatch_request
    rv = self.dispatch_request()
  File "/home/m0nd2y/.local/lib/python3.8/site-packages/flask/app.py", line 1469, in dispatch_request
    return self.ensure_sync(self.view_functions[rule.endpoint])(**view_args)
  File "/home/m0nd2y/.local/lib/python3.8/site-packages/flask_restx/api.py", line 404, in wrapper
    resp = resource(*args, **kwargs)
  File "/home/m0nd2y/.local/lib/python3.8/site-packages/flask/views.py", line 109, in view
    return current_app.ensure_sync(self.dispatch_request)(**kwargs)
  File "/home/m0nd2y/.local/lib/python3.8/site-packages/flask_restx/resource.py", line 46, in dispatch_request
    resp = meth(*args, **kwargs)
  File "/home/m0nd2y/SearchVuln/app.py", line 56, in post
    print(api.paylode)
  File "/home/m0nd2y/.local/lib/python3.8/site-packages/flask_restx/api.py", line 285, in __getattr__
    raise AttributeError("Api does not have {0} attribute".format(name))
AttributeError: Api does not have paylode attribute
127.0.0.1 - - [14/Jun/2023 05:54:01] "POST /SearchVuln/ HTTP/1.1" 200 -
127.0.0.1 - - [14/Jun/2023 05:54:01] "POST /SearchVuln/ HTTP/1.1" 200 -
127.0.0.1 - - [14/Jun/2023 05:54:01] "POST /SearchVuln/ HTTP/1.1" 200 -
127.0.0.1 - - [14/Jun/2023 05:54:01] "POST /SearchVuln/ HTTP/1.1" 200 -
163.152.3.132 - - [14/Jun/2023 05:57:53] "GET /api-docs HTTP/1.1" 200 -
163.152.3.132 - - [14/Jun/2023 05:57:54] "GET /swaggerui/droid-sans.css HTTP/1.1" 304 -
163.152.3.132 - - [14/Jun/2023 05:57:54] "GET /swaggerui/swagger-ui.css HTTP/1.1" 304 -
163.152.3.132 - - [14/Jun/2023 05:57:54] "GET /swaggerui/swagger-ui-standalone-preset.js HTTP/1.1" 304 -
163.152.3.132 - - [14/Jun/2023 05:57:54] "GET /swaggerui/swagger-ui-bundle.js HTTP/1.1" 304 -
163.152.3.132 - - [14/Jun/2023 05:57:54] "GET /swagger.json HTTP/1.1" 200 -
163.152.3.132 - - [14/Jun/2023 05:58:41] "POST /SearchDep/ HTTP/1.1" 500 -
Traceback (most recent call last):
  File "/home/m0nd2y/.local/lib/python3.8/site-packages/flask_restx/api.py", line 283, in __getattr__
    return getattr(self.default_namespace, name)
AttributeError: 'Namespace' object has no attribute 'paylode'

During handling of the above exception, another exception occurred:

Traceback (most recent call last):
  File "/home/m0nd2y/.local/lib/python3.8/site-packages/flask/app.py", line 2213, in __call__
    return self.wsgi_app(environ, start_response)
  File "/home/m0nd2y/.local/lib/python3.8/site-packages/flask/app.py", line 2193, in wsgi_app
    response = self.handle_exception(e)
  File "/home/m0nd2y/.local/lib/python3.8/site-packages/flask_restx/api.py", line 673, in error_router
    return original_handler(f)
  File "/home/m0nd2y/.local/lib/python3.8/site-packages/flask_restx/api.py", line 671, in error_router
    return self.handle_error(e)
  File "/home/m0nd2y/.local/lib/python3.8/site-packages/flask/app.py", line 2190, in wsgi_app
    response = self.full_dispatch_request()
  File "/home/m0nd2y/.local/lib/python3.8/site-packages/flask/app.py", line 1486, in full_dispatch_request
    rv = self.handle_user_exception(e)
  File "/home/m0nd2y/.local/lib/python3.8/site-packages/flask_restx/api.py", line 673, in error_router
    return original_handler(f)
  File "/home/m0nd2y/.local/lib/python3.8/site-packages/flask_restx/api.py", line 671, in error_router
    return self.handle_error(e)
  File "/home/m0nd2y/.local/lib/python3.8/site-packages/flask/app.py", line 1484, in full_dispatch_request
    rv = self.dispatch_request()
  File "/home/m0nd2y/.local/lib/python3.8/site-packages/flask/app.py", line 1469, in dispatch_request
    return self.ensure_sync(self.view_functions[rule.endpoint])(**view_args)
  File "/home/m0nd2y/.local/lib/python3.8/site-packages/flask_restx/api.py", line 404, in wrapper
    resp = resource(*args, **kwargs)
  File "/home/m0nd2y/.local/lib/python3.8/site-packages/flask/views.py", line 109, in view
    return current_app.ensure_sync(self.dispatch_request)(**kwargs)
  File "/home/m0nd2y/.local/lib/python3.8/site-packages/flask_restx/resource.py", line 46, in dispatch_request
    resp = meth(*args, **kwargs)
  File "/home/m0nd2y/SearchVuln/app.py", line 56, in post
    print(api.paylode)
  File "/home/m0nd2y/.local/lib/python3.8/site-packages/flask_restx/api.py", line 285, in __getattr__
    raise AttributeError("Api does not have {0} attribute".format(name))
AttributeError: Api does not have paylode attribute
163.152.3.140 - - [14/Jun/2023 08:54:18] "GET /api-docs HTTP/1.1" 200 -
163.152.3.140 - - [14/Jun/2023 08:54:18] "GET /swaggerui/swagger-ui.css HTTP/1.1" 200 -
163.152.3.140 - - [14/Jun/2023 08:54:18] "GET /swaggerui/swagger-ui-bundle.js HTTP/1.1" 200 -
163.152.3.140 - - [14/Jun/2023 08:54:19] "GET /swaggerui/droid-sans.css HTTP/1.1" 304 -
163.152.3.140 - - [14/Jun/2023 08:54:19] "GET /swaggerui/swagger-ui-standalone-preset.js HTTP/1.1" 200 -
163.152.3.140 - - [14/Jun/2023 08:54:21] "GET /swaggerui/favicon-32x32.png HTTP/1.1" 304 -
163.152.3.140 - - [14/Jun/2023 08:54:21] "GET /swagger.json HTTP/1.1" 200 -
163.152.3.140 - - [14/Jun/2023 08:54:32] "POST /SearchDep/ HTTP/1.1" 500 -
Traceback (most recent call last):
  File "/home/m0nd2y/.local/lib/python3.8/site-packages/flask_restx/api.py", line 283, in __getattr__
    return getattr(self.default_namespace, name)
AttributeError: 'Namespace' object has no attribute 'paylode'

During handling of the above exception, another exception occurred:

Traceback (most recent call last):
  File "/home/m0nd2y/.local/lib/python3.8/site-packages/flask/app.py", line 2213, in __call__
    return self.wsgi_app(environ, start_response)
  File "/home/m0nd2y/.local/lib/python3.8/site-packages/flask/app.py", line 2193, in wsgi_app
    response = self.handle_exception(e)
  File "/home/m0nd2y/.local/lib/python3.8/site-packages/flask_restx/api.py", line 673, in error_router
    return original_handler(f)
  File "/home/m0nd2y/.local/lib/python3.8/site-packages/flask_restx/api.py", line 671, in error_router
    return self.handle_error(e)
  File "/home/m0nd2y/.local/lib/python3.8/site-packages/flask/app.py", line 2190, in wsgi_app
    response = self.full_dispatch_request()
  File "/home/m0nd2y/.local/lib/python3.8/site-packages/flask/app.py", line 1486, in full_dispatch_request
    rv = self.handle_user_exception(e)
  File "/home/m0nd2y/.local/lib/python3.8/site-packages/flask_restx/api.py", line 673, in error_router
    return original_handler(f)
  File "/home/m0nd2y/.local/lib/python3.8/site-packages/flask_restx/api.py", line 671, in error_router
    return self.handle_error(e)
  File "/home/m0nd2y/.local/lib/python3.8/site-packages/flask/app.py", line 1484, in full_dispatch_request
    rv = self.dispatch_request()
  File "/home/m0nd2y/.local/lib/python3.8/site-packages/flask/app.py", line 1469, in dispatch_request
    return self.ensure_sync(self.view_functions[rule.endpoint])(**view_args)
  File "/home/m0nd2y/.local/lib/python3.8/site-packages/flask_restx/api.py", line 404, in wrapper
    resp = resource(*args, **kwargs)
  File "/home/m0nd2y/.local/lib/python3.8/site-packages/flask/views.py", line 109, in view
    return current_app.ensure_sync(self.dispatch_request)(**kwargs)
  File "/home/m0nd2y/.local/lib/python3.8/site-packages/flask_restx/resource.py", line 46, in dispatch_request
    resp = meth(*args, **kwargs)
  File "/home/m0nd2y/SearchVuln/app.py", line 56, in post
    print(api.paylode)
  File "/home/m0nd2y/.local/lib/python3.8/site-packages/flask_restx/api.py", line 285, in __getattr__
    raise AttributeError("Api does not have {0} attribute".format(name))
AttributeError: Api does not have paylode attribute
163.152.3.140 - - [14/Jun/2023 08:54:40] "GET /api-docs HTTP/1.1" 200 -
163.152.3.140 - - [14/Jun/2023 08:54:40] "GET /swaggerui/droid-sans.css HTTP/1.1" 304 -
163.152.3.140 - - [14/Jun/2023 08:54:40] "GET /swaggerui/swagger-ui.css HTTP/1.1" 304 -
163.152.3.140 - - [14/Jun/2023 08:54:40] "GET /swaggerui/swagger-ui-bundle.js HTTP/1.1" 304 -
163.152.3.140 - - [14/Jun/2023 08:54:40] "GET /swaggerui/swagger-ui-standalone-preset.js HTTP/1.1" 304 -
163.152.3.140 - - [14/Jun/2023 08:54:40] "GET /swaggerui/favicon-32x32.png HTTP/1.1" 304 -
163.152.3.140 - - [14/Jun/2023 08:54:41] "GET /swagger.json HTTP/1.1" 200 -
163.152.3.140 - - [14/Jun/2023 08:54:41] "GET /swaggerui/favicon-32x32.png HTTP/1.1" 304 -
163.152.3.140 - - [14/Jun/2023 08:54:45] "POST /SearchDep/ HTTP/1.1" 500 -
 * Debug mode: on
WARNING: This is a development server. Do not use it in a production deployment. Use a production WSGI server instead.
 * Running on all addresses (0.0.0.0)
 * Running on http://127.0.0.1:42598
 * Running on http://167.99.106.139:42598
Press CTRL+C to quit
 * Restarting with stat
 * Debugger is active!
 * Debugger PIN: 895-987-604
163.152.3.140 - - [14/Jun/2023 08:56:39] "GET /api-docs HTTP/1.1" 200 -
163.152.3.140 - - [14/Jun/2023 08:56:40] "GET /swaggerui/droid-sans.css HTTP/1.1" 304 -
163.152.3.140 - - [14/Jun/2023 08:56:40] "GET /swaggerui/swagger-ui-bundle.js HTTP/1.1" 304 -
163.152.3.140 - - [14/Jun/2023 08:56:40] "GET /swaggerui/swagger-ui.css HTTP/1.1" 304 -
163.152.3.140 - - [14/Jun/2023 08:56:40] "GET /swaggerui/swagger-ui-standalone-preset.js HTTP/1.1" 304 -
163.152.3.140 - - [14/Jun/2023 08:56:41] "GET /swaggerui/favicon-32x32.png HTTP/1.1" 304 -
163.152.3.140 - - [14/Jun/2023 08:56:41] "GET /swagger.json HTTP/1.1" 200 -
163.152.3.140 - - [14/Jun/2023 08:56:41] "GET /swaggerui/favicon-32x32.png HTTP/1.1" 304 -
163.152.3.140 - - [14/Jun/2023 08:56:47] "POST /SearchVuln/ HTTP/1.1" 200 -
163.152.3.140 - - [14/Jun/2023 08:56:51] "POST /SearchDep/ HTTP/1.1" 500 -
Traceback (most recent call last):
  File "/home/m0nd2y/.local/lib/python3.8/site-packages/flask_restx/api.py", line 283, in __getattr__
    return getattr(self.default_namespace, name)
AttributeError: 'Namespace' object has no attribute 'paylode'

During handling of the above exception, another exception occurred:

Traceback (most recent call last):
  File "/home/m0nd2y/.local/lib/python3.8/site-packages/flask/app.py", line 2213, in __call__
    return self.wsgi_app(environ, start_response)
  File "/home/m0nd2y/.local/lib/python3.8/site-packages/flask/app.py", line 2193, in wsgi_app
    response = self.handle_exception(e)
  File "/home/m0nd2y/.local/lib/python3.8/site-packages/flask_restx/api.py", line 673, in error_router
    return original_handler(f)
  File "/home/m0nd2y/.local/lib/python3.8/site-packages/flask_restx/api.py", line 671, in error_router
    return self.handle_error(e)
  File "/home/m0nd2y/.local/lib/python3.8/site-packages/flask/app.py", line 2190, in wsgi_app
    response = self.full_dispatch_request()
  File "/home/m0nd2y/.local/lib/python3.8/site-packages/flask/app.py", line 1486, in full_dispatch_request
    rv = self.handle_user_exception(e)
  File "/home/m0nd2y/.local/lib/python3.8/site-packages/flask_restx/api.py", line 673, in error_router
    return original_handler(f)
  File "/home/m0nd2y/.local/lib/python3.8/site-packages/flask_restx/api.py", line 671, in error_router
    return self.handle_error(e)
  File "/home/m0nd2y/.local/lib/python3.8/site-packages/flask/app.py", line 1484, in full_dispatch_request
    rv = self.dispatch_request()
  File "/home/m0nd2y/.local/lib/python3.8/site-packages/flask/app.py", line 1469, in dispatch_request
    return self.ensure_sync(self.view_functions[rule.endpoint])(**view_args)
  File "/home/m0nd2y/.local/lib/python3.8/site-packages/flask_restx/api.py", line 404, in wrapper
    resp = resource(*args, **kwargs)
  File "/home/m0nd2y/.local/lib/python3.8/site-packages/flask/views.py", line 109, in view
    return current_app.ensure_sync(self.dispatch_request)(**kwargs)
  File "/home/m0nd2y/.local/lib/python3.8/site-packages/flask_restx/resource.py", line 46, in dispatch_request
    resp = meth(*args, **kwargs)
  File "/home/m0nd2y/SearchVuln/app.py", line 56, in post
    print(api.paylode)
  File "/home/m0nd2y/.local/lib/python3.8/site-packages/flask_restx/api.py", line 285, in __getattr__
    raise AttributeError("Api does not have {0} attribute".format(name))
AttributeError: Api does not have paylode attribute
163.152.3.140 - - [14/Jun/2023 08:58:26] "POST /SearchDep/ HTTP/1.1" 500 -
Traceback (most recent call last):
  File "/home/m0nd2y/.local/lib/python3.8/site-packages/flask_restx/api.py", line 283, in __getattr__
    return getattr(self.default_namespace, name)
AttributeError: 'Namespace' object has no attribute 'paylode'

During handling of the above exception, another exception occurred:

Traceback (most recent call last):
  File "/home/m0nd2y/.local/lib/python3.8/site-packages/flask/app.py", line 2213, in __call__
    return self.wsgi_app(environ, start_response)
  File "/home/m0nd2y/.local/lib/python3.8/site-packages/flask/app.py", line 2193, in wsgi_app
    response = self.handle_exception(e)
  File "/home/m0nd2y/.local/lib/python3.8/site-packages/flask_restx/api.py", line 673, in error_router
    return original_handler(f)
  File "/home/m0nd2y/.local/lib/python3.8/site-packages/flask_restx/api.py", line 671, in error_router
    return self.handle_error(e)
  File "/home/m0nd2y/.local/lib/python3.8/site-packages/flask/app.py", line 2190, in wsgi_app
    response = self.full_dispatch_request()
  File "/home/m0nd2y/.local/lib/python3.8/site-packages/flask/app.py", line 1486, in full_dispatch_request
    rv = self.handle_user_exception(e)
  File "/home/m0nd2y/.local/lib/python3.8/site-packages/flask_restx/api.py", line 673, in error_router
    return original_handler(f)
  File "/home/m0nd2y/.local/lib/python3.8/site-packages/flask_restx/api.py", line 671, in error_router
    return self.handle_error(e)
  File "/home/m0nd2y/.local/lib/python3.8/site-packages/flask/app.py", line 1484, in full_dispatch_request
    rv = self.dispatch_request()
  File "/home/m0nd2y/.local/lib/python3.8/site-packages/flask/app.py", line 1469, in dispatch_request
    return self.ensure_sync(self.view_functions[rule.endpoint])(**view_args)
  File "/home/m0nd2y/.local/lib/python3.8/site-packages/flask_restx/api.py", line 404, in wrapper
    resp = resource(*args, **kwargs)
  File "/home/m0nd2y/.local/lib/python3.8/site-packages/flask/views.py", line 109, in view
    return current_app.ensure_sync(self.dispatch_request)(**kwargs)
  File "/home/m0nd2y/.local/lib/python3.8/site-packages/flask_restx/resource.py", line 46, in dispatch_request
    resp = meth(*args, **kwargs)
  File "/home/m0nd2y/SearchVuln/app.py", line 56, in post
    print(api.paylode)
  File "/home/m0nd2y/.local/lib/python3.8/site-packages/flask_restx/api.py", line 285, in __getattr__
    raise AttributeError("Api does not have {0} attribute".format(name))
AttributeError: Api does not have paylode attribute
 * Detected change in '/home/m0nd2y/SearchVuln/app.py', reloading
 * Restarting with stat
 * Debugger is active!
 * Debugger PIN: 895-987-604
163.152.3.140 - - [14/Jun/2023 09:29:00] "POST /SearchDep/ HTTP/1.1" 500 -
Traceback (most recent call last):
  File "/home/m0nd2y/.local/lib/python3.8/site-packages/flask_restx/api.py", line 283, in __getattr__
    return getattr(self.default_namespace, name)
AttributeError: 'Namespace' object has no attribute 'paylode'

During handling of the above exception, another exception occurred:

Traceback (most recent call last):
  File "/home/m0nd2y/.local/lib/python3.8/site-packages/flask/app.py", line 2213, in __call__
    return self.wsgi_app(environ, start_response)
  File "/home/m0nd2y/.local/lib/python3.8/site-packages/flask/app.py", line 2193, in wsgi_app
    response = self.handle_exception(e)
  File "/home/m0nd2y/.local/lib/python3.8/site-packages/flask_restx/api.py", line 673, in error_router
    return original_handler(f)
  File "/home/m0nd2y/.local/lib/python3.8/site-packages/flask_restx/api.py", line 671, in error_router
    return self.handle_error(e)
  File "/home/m0nd2y/.local/lib/python3.8/site-packages/flask/app.py", line 2190, in wsgi_app
    response = self.full_dispatch_request()
  File "/home/m0nd2y/.local/lib/python3.8/site-packages/flask/app.py", line 1486, in full_dispatch_request
    rv = self.handle_user_exception(e)
  File "/home/m0nd2y/.local/lib/python3.8/site-packages/flask_restx/api.py", line 673, in error_router
    return original_handler(f)
  File "/home/m0nd2y/.local/lib/python3.8/site-packages/flask_restx/api.py", line 671, in error_router
    return self.handle_error(e)
  File "/home/m0nd2y/.local/lib/python3.8/site-packages/flask/app.py", line 1484, in full_dispatch_request
    rv = self.dispatch_request()
  File "/home/m0nd2y/.local/lib/python3.8/site-packages/flask/app.py", line 1469, in dispatch_request
    return self.ensure_sync(self.view_functions[rule.endpoint])(**view_args)
  File "/home/m0nd2y/.local/lib/python3.8/site-packages/flask_restx/api.py", line 404, in wrapper
    resp = resource(*args, **kwargs)
  File "/home/m0nd2y/.local/lib/python3.8/site-packages/flask/views.py", line 109, in view
    return current_app.ensure_sync(self.dispatch_request)(**kwargs)
  File "/home/m0nd2y/.local/lib/python3.8/site-packages/flask_restx/resource.py", line 46, in dispatch_request
    resp = meth(*args, **kwargs)
  File "/home/m0nd2y/SearchVuln/app.py", line 57, in post
    print(api.paylode)
  File "/home/m0nd2y/.local/lib/python3.8/site-packages/flask_restx/api.py", line 285, in __getattr__
    raise AttributeError("Api does not have {0} attribute".format(name))
AttributeError: Api does not have paylode attribute
163.152.3.140 - - [14/Jun/2023 09:29:28] "GET /SearchDep/ HTTP/1.1" 405 -
163.152.3.140 - - [14/Jun/2023 09:29:28] "GET /favicon.ico HTTP/1.1" 404 -
 * Detected change in '/home/m0nd2y/SearchVuln/app.py', reloading


hello


 * Restarting with stat
 * Debugger is active!
 * Debugger PIN: 895-987-604
 * Detected change in '/home/m0nd2y/SearchVuln/app.py', reloading
 * Restarting with stat
 * Debugger is active!
 * Debugger PIN: 895-987-604
163.152.3.140 - - [14/Jun/2023 09:30:39] "POST /SearchDep/ HTTP/1.1" 200 -
Collecting brotlipy==0.7.0
  Using cached brotlipy-0.7.0-cp38-cp38-manylinux1_x86_64.whl (1.1 MB)
Collecting certifi==2022.12.7
  Using cached certifi-2022.12.7-py3-none-any.whl (155 kB)
Collecting cffi==1.15.1
  Using cached cffi-1.15.1-cp38-cp38-manylinux_2_17_x86_64.manylinux2014_x86_64.whl (442 kB)
Collecting pycparser
  Using cached pycparser-2.21-py2.py3-none-any.whl (118 kB)
Installing collected packages: pycparser, cffi, brotlipy, certifi
Successfully installed brotlipy-0.7.0 certifi-2022.12.7 cffi-1.15.1 pycparser-2.21
Collecting pipdeptree
  Using cached pipdeptree-2.9.0-py3-none-any.whl (18 kB)
Installing collected packages: pipdeptree
Successfully installed pipdeptree-2.9.0
Collecting graphviz
  Using cached graphviz-0.20.1-py3-none-any.whl (47 kB)
Installing collected packages: graphviz
Successfully installed graphviz-0.20.1
 * Detected change in '/home/m0nd2y/SearchVuln/app.py', reloading
 * Restarting with stat
 * Debugger is active!
 * Debugger PIN: 895-987-604
